TensorFlow installation not found - running with reduced feature set.
TensorBoard 2.14.0 at http://dl3090-03:6006/ (Press CTRL+C to quit)
E0309 14:28:50.377402 140526076073728 _internal.py:97] Error on request:
Traceback (most recent call last):
  File "/media/ntu/volume1/home/s124md303_06/.local/lib/python3.8/site-packages/werkzeug/serving.py", line 370, in run_wsgi
    execute(self.server.app)
  File "/media/ntu/volume1/home/s124md303_06/.local/lib/python3.8/site-packages/werkzeug/serving.py", line 331, in execute
    application_iter = app(environ, start_response)
  File "/media/ntu/volume1/home/s124md303_06/.local/lib/python3.8/site-packages/tensorboard/backend/application.py", line 528, in __call__
    return self._app(environ, start_response)
  File "/media/ntu/volume1/home/s124md303_06/.local/lib/python3.8/site-packages/tensorboard/backend/application.py", line 569, in wrapper
    return wsgi_app(environ, start_response)
  File "/media/ntu/volume1/home/s124md303_06/.local/lib/python3.8/site-packages/tensorboard/backend/security_validator.py", line 91, in __call__
    return self._application(environ, start_response_proxy)
  File "/media/ntu/volume1/home/s124md303_06/.local/lib/python3.8/site-packages/tensorboard/backend/path_prefix.py", line 68, in __call__
    return self._application(environ, start_response)
  File "/media/ntu/volume1/home/s124md303_06/.local/lib/python3.8/site-packages/tensorboard/backend/experiment_id.py", line 73, in __call__
    return self._application(environ, start_response)
  File "/media/ntu/volume1/home/s124md303_06/.local/lib/python3.8/site-packages/tensorboard/backend/empty_path_redirect.py", line 43, in __call__
    return self._application(environ, start_response)
  File "/media/ntu/volume1/home/s124md303_06/.local/lib/python3.8/site-packages/tensorboard/backend/client_feature_flags.py", line 55, in __call__
    return self._application(environ, start_response)
  File "/media/ntu/volume1/home/s124md303_06/.local/lib/python3.8/site-packages/tensorboard/backend/auth_context_middleware.py", line 38, in __call__
    return self._application(environ, start_response)
  File "/media/ntu/volume1/home/s124md303_06/.local/lib/python3.8/site-packages/tensorboard/backend/application.py", line 551, in _route_request
    return self.exact_routes[clean_path](environ, start_response)
  File "/media/ntu/volume1/home/s124md303_06/.local/lib/python3.8/site-packages/werkzeug/wrappers/request.py", line 190, in application
    resp = f(*args[:-2] + (request,))
  File "/media/ntu/volume1/home/s124md303_06/.local/lib/python3.8/site-packages/tensorboard/plugins/hparams/hparams_plugin.py", line 122, in get_experiment_route
    json_format.MessageToJson(
TypeError: MessageToJson() got an unexpected keyword argument 'including_default_value_fields'
E0309 14:28:50.500371 140526042502912 _internal.py:97] Error on request:
Traceback (most recent call last):
  File "/media/ntu/volume1/home/s124md303_06/.local/lib/python3.8/site-packages/werkzeug/serving.py", line 370, in run_wsgi
    execute(self.server.app)
  File "/media/ntu/volume1/home/s124md303_06/.local/lib/python3.8/site-packages/werkzeug/serving.py", line 331, in execute
    application_iter = app(environ, start_response)
  File "/media/ntu/volume1/home/s124md303_06/.local/lib/python3.8/site-packages/tensorboard/backend/application.py", line 528, in __call__
    return self._app(environ, start_response)
  File "/media/ntu/volume1/home/s124md303_06/.local/lib/python3.8/site-packages/tensorboard/backend/application.py", line 569, in wrapper
    return wsgi_app(environ, start_response)
  File "/media/ntu/volume1/home/s124md303_06/.local/lib/python3.8/site-packages/tensorboard/backend/security_validator.py", line 91, in __call__
    return self._application(environ, start_response_proxy)
  File "/media/ntu/volume1/home/s124md303_06/.local/lib/python3.8/site-packages/tensorboard/backend/path_prefix.py", line 68, in __call__
    return self._application(environ, start_response)
  File "/media/ntu/volume1/home/s124md303_06/.local/lib/python3.8/site-packages/tensorboard/backend/experiment_id.py", line 73, in __call__
    return self._application(environ, start_response)
  File "/media/ntu/volume1/home/s124md303_06/.local/lib/python3.8/site-packages/tensorboard/backend/empty_path_redirect.py", line 43, in __call__
    return self._application(environ, start_response)
  File "/media/ntu/volume1/home/s124md303_06/.local/lib/python3.8/site-packages/tensorboard/backend/client_feature_flags.py", line 55, in __call__
    return self._application(environ, start_response)
  File "/media/ntu/volume1/home/s124md303_06/.local/lib/python3.8/site-packages/tensorboard/backend/auth_context_middleware.py", line 38, in __call__
    return self._application(environ, start_response)
  File "/media/ntu/volume1/home/s124md303_06/.local/lib/python3.8/site-packages/tensorboard/backend/application.py", line 551, in _route_request
    return self.exact_routes[clean_path](environ, start_response)
  File "/media/ntu/volume1/home/s124md303_06/.local/lib/python3.8/site-packages/werkzeug/wrappers/request.py", line 190, in application
    resp = f(*args[:-2] + (request,))
  File "/media/ntu/volume1/home/s124md303_06/.local/lib/python3.8/site-packages/tensorboard/plugins/hparams/hparams_plugin.py", line 122, in get_experiment_route
    json_format.MessageToJson(
TypeError: MessageToJson() got an unexpected keyword argument 'including_default_value_fields'
E0309 14:28:54.233117 140526825768704 _internal.py:97] Error on request:
Traceback (most recent call last):
  File "/media/ntu/volume1/home/s124md303_06/.local/lib/python3.8/site-packages/werkzeug/serving.py", line 370, in run_wsgi
    execute(self.server.app)
  File "/media/ntu/volume1/home/s124md303_06/.local/lib/python3.8/site-packages/werkzeug/serving.py", line 331, in execute
    application_iter = app(environ, start_response)
  File "/media/ntu/volume1/home/s124md303_06/.local/lib/python3.8/site-packages/tensorboard/backend/application.py", line 528, in __call__
    return self._app(environ, start_response)
  File "/media/ntu/volume1/home/s124md303_06/.local/lib/python3.8/site-packages/tensorboard/backend/application.py", line 569, in wrapper
    return wsgi_app(environ, start_response)
  File "/media/ntu/volume1/home/s124md303_06/.local/lib/python3.8/site-packages/tensorboard/backend/security_validator.py", line 91, in __call__
    return self._application(environ, start_response_proxy)
  File "/media/ntu/volume1/home/s124md303_06/.local/lib/python3.8/site-packages/tensorboard/backend/path_prefix.py", line 68, in __call__
    return self._application(environ, start_response)
  File "/media/ntu/volume1/home/s124md303_06/.local/lib/python3.8/site-packages/tensorboard/backend/experiment_id.py", line 73, in __call__
    return self._application(environ, start_response)
  File "/media/ntu/volume1/home/s124md303_06/.local/lib/python3.8/site-packages/tensorboard/backend/empty_path_redirect.py", line 43, in __call__
    return self._application(environ, start_response)
  File "/media/ntu/volume1/home/s124md303_06/.local/lib/python3.8/site-packages/tensorboard/backend/client_feature_flags.py", line 55, in __call__
    return self._application(environ, start_response)
  File "/media/ntu/volume1/home/s124md303_06/.local/lib/python3.8/site-packages/tensorboard/backend/auth_context_middleware.py", line 38, in __call__
    return self._application(environ, start_response)
  File "/media/ntu/volume1/home/s124md303_06/.local/lib/python3.8/site-packages/tensorboard/backend/application.py", line 551, in _route_request
    return self.exact_routes[clean_path](environ, start_response)
  File "/media/ntu/volume1/home/s124md303_06/.local/lib/python3.8/site-packages/werkzeug/wrappers/request.py", line 190, in application
    resp = f(*args[:-2] + (request,))
  File "/media/ntu/volume1/home/s124md303_06/.local/lib/python3.8/site-packages/tensorboard/plugins/hparams/hparams_plugin.py", line 122, in get_experiment_route
    json_format.MessageToJson(
TypeError: MessageToJson() got an unexpected keyword argument 'including_default_value_fields'
E0309 14:28:54.337338 140526825768704 _internal.py:97] Error on request:
Traceback (most recent call last):
  File "/media/ntu/volume1/home/s124md303_06/.local/lib/python3.8/site-packages/werkzeug/serving.py", line 370, in run_wsgi
    execute(self.server.app)
  File "/media/ntu/volume1/home/s124md303_06/.local/lib/python3.8/site-packages/werkzeug/serving.py", line 331, in execute
    application_iter = app(environ, start_response)
  File "/media/ntu/volume1/home/s124md303_06/.local/lib/python3.8/site-packages/tensorboard/backend/application.py", line 528, in __call__
    return self._app(environ, start_response)
  File "/media/ntu/volume1/home/s124md303_06/.local/lib/python3.8/site-packages/tensorboard/backend/application.py", line 569, in wrapper
    return wsgi_app(environ, start_response)
  File "/media/ntu/volume1/home/s124md303_06/.local/lib/python3.8/site-packages/tensorboard/backend/security_validator.py", line 91, in __call__
    return self._application(environ, start_response_proxy)
  File "/media/ntu/volume1/home/s124md303_06/.local/lib/python3.8/site-packages/tensorboard/backend/path_prefix.py", line 68, in __call__
    return self._application(environ, start_response)
  File "/media/ntu/volume1/home/s124md303_06/.local/lib/python3.8/site-packages/tensorboard/backend/experiment_id.py", line 73, in __call__
    return self._application(environ, start_response)
  File "/media/ntu/volume1/home/s124md303_06/.local/lib/python3.8/site-packages/tensorboard/backend/empty_path_redirect.py", line 43, in __call__
    return self._application(environ, start_response)
  File "/media/ntu/volume1/home/s124md303_06/.local/lib/python3.8/site-packages/tensorboard/backend/client_feature_flags.py", line 55, in __call__
    return self._application(environ, start_response)
  File "/media/ntu/volume1/home/s124md303_06/.local/lib/python3.8/site-packages/tensorboard/backend/auth_context_middleware.py", line 38, in __call__
    return self._application(environ, start_response)
  File "/media/ntu/volume1/home/s124md303_06/.local/lib/python3.8/site-packages/tensorboard/backend/application.py", line 551, in _route_request
    return self.exact_routes[clean_path](environ, start_response)
  File "/media/ntu/volume1/home/s124md303_06/.local/lib/python3.8/site-packages/werkzeug/wrappers/request.py", line 190, in application
    resp = f(*args[:-2] + (request,))
  File "/media/ntu/volume1/home/s124md303_06/.local/lib/python3.8/site-packages/tensorboard/plugins/hparams/hparams_plugin.py", line 122, in get_experiment_route
    json_format.MessageToJson(
TypeError: MessageToJson() got an unexpected keyword argument 'including_default_value_fields'
E0309 14:28:58.483377 140526825768704 _internal.py:97] Error on request:
Traceback (most recent call last):
  File "/media/ntu/volume1/home/s124md303_06/.local/lib/python3.8/site-packages/werkzeug/serving.py", line 370, in run_wsgi
    execute(self.server.app)
  File "/media/ntu/volume1/home/s124md303_06/.local/lib/python3.8/site-packages/werkzeug/serving.py", line 331, in execute
    application_iter = app(environ, start_response)
  File "/media/ntu/volume1/home/s124md303_06/.local/lib/python3.8/site-packages/tensorboard/backend/application.py", line 528, in __call__
    return self._app(environ, start_response)
  File "/media/ntu/volume1/home/s124md303_06/.local/lib/python3.8/site-packages/tensorboard/backend/application.py", line 569, in wrapper
    return wsgi_app(environ, start_response)
  File "/media/ntu/volume1/home/s124md303_06/.local/lib/python3.8/site-packages/tensorboard/backend/security_validator.py", line 91, in __call__
    return self._application(environ, start_response_proxy)
  File "/media/ntu/volume1/home/s124md303_06/.local/lib/python3.8/site-packages/tensorboard/backend/path_prefix.py", line 68, in __call__
    return self._application(environ, start_response)
  File "/media/ntu/volume1/home/s124md303_06/.local/lib/python3.8/site-packages/tensorboard/backend/experiment_id.py", line 73, in __call__
    return self._application(environ, start_response)
  File "/media/ntu/volume1/home/s124md303_06/.local/lib/python3.8/site-packages/tensorboard/backend/empty_path_redirect.py", line 43, in __call__
    return self._application(environ, start_response)
  File "/media/ntu/volume1/home/s124md303_06/.local/lib/python3.8/site-packages/tensorboard/backend/client_feature_flags.py", line 55, in __call__
    return self._application(environ, start_response)
  File "/media/ntu/volume1/home/s124md303_06/.local/lib/python3.8/site-packages/tensorboard/backend/auth_context_middleware.py", line 38, in __call__
    return self._application(environ, start_response)
  File "/media/ntu/volume1/home/s124md303_06/.local/lib/python3.8/site-packages/tensorboard/backend/application.py", line 551, in _route_request
    return self.exact_routes[clean_path](environ, start_response)
  File "/media/ntu/volume1/home/s124md303_06/.local/lib/python3.8/site-packages/werkzeug/wrappers/request.py", line 190, in application
    resp = f(*args[:-2] + (request,))
  File "/media/ntu/volume1/home/s124md303_06/.local/lib/python3.8/site-packages/tensorboard/plugins/hparams/hparams_plugin.py", line 122, in get_experiment_route
    json_format.MessageToJson(
TypeError: MessageToJson() got an unexpected keyword argument 'including_default_value_fields'
E0309 14:28:58.615333 140527446648576 _internal.py:97] Error on request:
Traceback (most recent call last):
  File "/media/ntu/volume1/home/s124md303_06/.local/lib/python3.8/site-packages/werkzeug/serving.py", line 370, in run_wsgi
    execute(self.server.app)
  File "/media/ntu/volume1/home/s124md303_06/.local/lib/python3.8/site-packages/werkzeug/serving.py", line 331, in execute
    application_iter = app(environ, start_response)
  File "/media/ntu/volume1/home/s124md303_06/.local/lib/python3.8/site-packages/tensorboard/backend/application.py", line 528, in __call__
    return self._app(environ, start_response)
  File "/media/ntu/volume1/home/s124md303_06/.local/lib/python3.8/site-packages/tensorboard/backend/application.py", line 569, in wrapper
    return wsgi_app(environ, start_response)
  File "/media/ntu/volume1/home/s124md303_06/.local/lib/python3.8/site-packages/tensorboard/backend/security_validator.py", line 91, in __call__
    return self._application(environ, start_response_proxy)
  File "/media/ntu/volume1/home/s124md303_06/.local/lib/python3.8/site-packages/tensorboard/backend/path_prefix.py", line 68, in __call__
    return self._application(environ, start_response)
  File "/media/ntu/volume1/home/s124md303_06/.local/lib/python3.8/site-packages/tensorboard/backend/experiment_id.py", line 73, in __call__
    return self._application(environ, start_response)
  File "/media/ntu/volume1/home/s124md303_06/.local/lib/python3.8/site-packages/tensorboard/backend/empty_path_redirect.py", line 43, in __call__
    return self._application(environ, start_response)
  File "/media/ntu/volume1/home/s124md303_06/.local/lib/python3.8/site-packages/tensorboard/backend/client_feature_flags.py", line 55, in __call__
    return self._application(environ, start_response)
  File "/media/ntu/volume1/home/s124md303_06/.local/lib/python3.8/site-packages/tensorboard/backend/auth_context_middleware.py", line 38, in __call__
    return self._application(environ, start_response)
  File "/media/ntu/volume1/home/s124md303_06/.local/lib/python3.8/site-packages/tensorboard/backend/application.py", line 551, in _route_request
    return self.exact_routes[clean_path](environ, start_response)
  File "/media/ntu/volume1/home/s124md303_06/.local/lib/python3.8/site-packages/werkzeug/wrappers/request.py", line 190, in application
    resp = f(*args[:-2] + (request,))
  File "/media/ntu/volume1/home/s124md303_06/.local/lib/python3.8/site-packages/tensorboard/plugins/hparams/hparams_plugin.py", line 122, in get_experiment_route
    json_format.MessageToJson(
TypeError: MessageToJson() got an unexpected keyword argument 'including_default_value_fields'
E0309 14:29:28.504333 140526076073728 _internal.py:97] Error on request:
Traceback (most recent call last):
  File "/media/ntu/volume1/home/s124md303_06/.local/lib/python3.8/site-packages/werkzeug/serving.py", line 370, in run_wsgi
    execute(self.server.app)
  File "/media/ntu/volume1/home/s124md303_06/.local/lib/python3.8/site-packages/werkzeug/serving.py", line 331, in execute
    application_iter = app(environ, start_response)
  File "/media/ntu/volume1/home/s124md303_06/.local/lib/python3.8/site-packages/tensorboard/backend/application.py", line 528, in __call__
    return self._app(environ, start_response)
  File "/media/ntu/volume1/home/s124md303_06/.local/lib/python3.8/site-packages/tensorboard/backend/application.py", line 569, in wrapper
    return wsgi_app(environ, start_response)
  File "/media/ntu/volume1/home/s124md303_06/.local/lib/python3.8/site-packages/tensorboard/backend/security_validator.py", line 91, in __call__
    return self._application(environ, start_response_proxy)
  File "/media/ntu/volume1/home/s124md303_06/.local/lib/python3.8/site-packages/tensorboard/backend/path_prefix.py", line 68, in __call__
    return self._application(environ, start_response)
  File "/media/ntu/volume1/home/s124md303_06/.local/lib/python3.8/site-packages/tensorboard/backend/experiment_id.py", line 73, in __call__
    return self._application(environ, start_response)
  File "/media/ntu/volume1/home/s124md303_06/.local/lib/python3.8/site-packages/tensorboard/backend/empty_path_redirect.py", line 43, in __call__
    return self._application(environ, start_response)
  File "/media/ntu/volume1/home/s124md303_06/.local/lib/python3.8/site-packages/tensorboard/backend/client_feature_flags.py", line 55, in __call__
    return self._application(environ, start_response)
  File "/media/ntu/volume1/home/s124md303_06/.local/lib/python3.8/site-packages/tensorboard/backend/auth_context_middleware.py", line 38, in __call__
    return self._application(environ, start_response)
  File "/media/ntu/volume1/home/s124md303_06/.local/lib/python3.8/site-packages/tensorboard/backend/application.py", line 551, in _route_request
    return self.exact_routes[clean_path](environ, start_response)
  File "/media/ntu/volume1/home/s124md303_06/.local/lib/python3.8/site-packages/werkzeug/wrappers/request.py", line 190, in application
    resp = f(*args[:-2] + (request,))
  File "/media/ntu/volume1/home/s124md303_06/.local/lib/python3.8/site-packages/tensorboard/plugins/hparams/hparams_plugin.py", line 122, in get_experiment_route
    json_format.MessageToJson(
TypeError: MessageToJson() got an unexpected keyword argument 'including_default_value_fields'
E0309 14:29:58.504550 140527404701440 _internal.py:97] Error on request:
Traceback (most recent call last):
  File "/media/ntu/volume1/home/s124md303_06/.local/lib/python3.8/site-packages/werkzeug/serving.py", line 370, in run_wsgi
    execute(self.server.app)
  File "/media/ntu/volume1/home/s124md303_06/.local/lib/python3.8/site-packages/werkzeug/serving.py", line 331, in execute
    application_iter = app(environ, start_response)
  File "/media/ntu/volume1/home/s124md303_06/.local/lib/python3.8/site-packages/tensorboard/backend/application.py", line 528, in __call__
    return self._app(environ, start_response)
  File "/media/ntu/volume1/home/s124md303_06/.local/lib/python3.8/site-packages/tensorboard/backend/application.py", line 569, in wrapper
    return wsgi_app(environ, start_response)
  File "/media/ntu/volume1/home/s124md303_06/.local/lib/python3.8/site-packages/tensorboard/backend/security_validator.py", line 91, in __call__
    return self._application(environ, start_response_proxy)
  File "/media/ntu/volume1/home/s124md303_06/.local/lib/python3.8/site-packages/tensorboard/backend/path_prefix.py", line 68, in __call__
    return self._application(environ, start_response)
  File "/media/ntu/volume1/home/s124md303_06/.local/lib/python3.8/site-packages/tensorboard/backend/experiment_id.py", line 73, in __call__
    return self._application(environ, start_response)
  File "/media/ntu/volume1/home/s124md303_06/.local/lib/python3.8/site-packages/tensorboard/backend/empty_path_redirect.py", line 43, in __call__
    return self._application(environ, start_response)
  File "/media/ntu/volume1/home/s124md303_06/.local/lib/python3.8/site-packages/tensorboard/backend/client_feature_flags.py", line 55, in __call__
    return self._application(environ, start_response)
  File "/media/ntu/volume1/home/s124md303_06/.local/lib/python3.8/site-packages/tensorboard/backend/auth_context_middleware.py", line 38, in __call__
    return self._application(environ, start_response)
  File "/media/ntu/volume1/home/s124md303_06/.local/lib/python3.8/site-packages/tensorboard/backend/application.py", line 551, in _route_request
    return self.exact_routes[clean_path](environ, start_response)
  File "/media/ntu/volume1/home/s124md303_06/.local/lib/python3.8/site-packages/werkzeug/wrappers/request.py", line 190, in application
    resp = f(*args[:-2] + (request,))
  File "/media/ntu/volume1/home/s124md303_06/.local/lib/python3.8/site-packages/tensorboard/plugins/hparams/hparams_plugin.py", line 122, in get_experiment_route
    json_format.MessageToJson(
TypeError: MessageToJson() got an unexpected keyword argument 'including_default_value_fields'
E0309 14:30:28.514519 140527530542848 _internal.py:97] Error on request:
Traceback (most recent call last):
  File "/media/ntu/volume1/home/s124md303_06/.local/lib/python3.8/site-packages/werkzeug/serving.py", line 370, in run_wsgi
    execute(self.server.app)
  File "/media/ntu/volume1/home/s124md303_06/.local/lib/python3.8/site-packages/werkzeug/serving.py", line 331, in execute
    application_iter = app(environ, start_response)
  File "/media/ntu/volume1/home/s124md303_06/.local/lib/python3.8/site-packages/tensorboard/backend/application.py", line 528, in __call__
    return self._app(environ, start_response)
  File "/media/ntu/volume1/home/s124md303_06/.local/lib/python3.8/site-packages/tensorboard/backend/application.py", line 569, in wrapper
    return wsgi_app(environ, start_response)
  File "/media/ntu/volume1/home/s124md303_06/.local/lib/python3.8/site-packages/tensorboard/backend/security_validator.py", line 91, in __call__
    return self._application(environ, start_response_proxy)
  File "/media/ntu/volume1/home/s124md303_06/.local/lib/python3.8/site-packages/tensorboard/backend/path_prefix.py", line 68, in __call__
    return self._application(environ, start_response)
  File "/media/ntu/volume1/home/s124md303_06/.local/lib/python3.8/site-packages/tensorboard/backend/experiment_id.py", line 73, in __call__
    return self._application(environ, start_response)
  File "/media/ntu/volume1/home/s124md303_06/.local/lib/python3.8/site-packages/tensorboard/backend/empty_path_redirect.py", line 43, in __call__
    return self._application(environ, start_response)
  File "/media/ntu/volume1/home/s124md303_06/.local/lib/python3.8/site-packages/tensorboard/backend/client_feature_flags.py", line 55, in __call__
    return self._application(environ, start_response)
  File "/media/ntu/volume1/home/s124md303_06/.local/lib/python3.8/site-packages/tensorboard/backend/auth_context_middleware.py", line 38, in __call__
    return self._application(environ, start_response)
  File "/media/ntu/volume1/home/s124md303_06/.local/lib/python3.8/site-packages/tensorboard/backend/application.py", line 551, in _route_request
    return self.exact_routes[clean_path](environ, start_response)
  File "/media/ntu/volume1/home/s124md303_06/.local/lib/python3.8/site-packages/werkzeug/wrappers/request.py", line 190, in application
    resp = f(*args[:-2] + (request,))
  File "/media/ntu/volume1/home/s124md303_06/.local/lib/python3.8/site-packages/tensorboard/plugins/hparams/hparams_plugin.py", line 122, in get_experiment_route
    json_format.MessageToJson(
TypeError: MessageToJson() got an unexpected keyword argument 'including_default_value_fields'
E0309 14:30:58.515960 140527580358400 _internal.py:97] Error on request:
Traceback (most recent call last):
  File "/media/ntu/volume1/home/s124md303_06/.local/lib/python3.8/site-packages/werkzeug/serving.py", line 370, in run_wsgi
    execute(self.server.app)
  File "/media/ntu/volume1/home/s124md303_06/.local/lib/python3.8/site-packages/werkzeug/serving.py", line 331, in execute
    application_iter = app(environ, start_response)
  File "/media/ntu/volume1/home/s124md303_06/.local/lib/python3.8/site-packages/tensorboard/backend/application.py", line 528, in __call__
    return self._app(environ, start_response)
  File "/media/ntu/volume1/home/s124md303_06/.local/lib/python3.8/site-packages/tensorboard/backend/application.py", line 569, in wrapper
    return wsgi_app(environ, start_response)
  File "/media/ntu/volume1/home/s124md303_06/.local/lib/python3.8/site-packages/tensorboard/backend/security_validator.py", line 91, in __call__
    return self._application(environ, start_response_proxy)
  File "/media/ntu/volume1/home/s124md303_06/.local/lib/python3.8/site-packages/tensorboard/backend/path_prefix.py", line 68, in __call__
    return self._application(environ, start_response)
  File "/media/ntu/volume1/home/s124md303_06/.local/lib/python3.8/site-packages/tensorboard/backend/experiment_id.py", line 73, in __call__
    return self._application(environ, start_response)
  File "/media/ntu/volume1/home/s124md303_06/.local/lib/python3.8/site-packages/tensorboard/backend/empty_path_redirect.py", line 43, in __call__
    return self._application(environ, start_response)
  File "/media/ntu/volume1/home/s124md303_06/.local/lib/python3.8/site-packages/tensorboard/backend/client_feature_flags.py", line 55, in __call__
    return self._application(environ, start_response)
  File "/media/ntu/volume1/home/s124md303_06/.local/lib/python3.8/site-packages/tensorboard/backend/auth_context_middleware.py", line 38, in __call__
    return self._application(environ, start_response)
  File "/media/ntu/volume1/home/s124md303_06/.local/lib/python3.8/site-packages/tensorboard/backend/application.py", line 551, in _route_request
    return self.exact_routes[clean_path](environ, start_response)
  File "/media/ntu/volume1/home/s124md303_06/.local/lib/python3.8/site-packages/werkzeug/wrappers/request.py", line 190, in application
    resp = f(*args[:-2] + (request,))
  File "/media/ntu/volume1/home/s124md303_06/.local/lib/python3.8/site-packages/tensorboard/plugins/hparams/hparams_plugin.py", line 122, in get_experiment_route
    json_format.MessageToJson(
TypeError: MessageToJson() got an unexpected keyword argument 'including_default_value_fields'
E0309 14:31:28.528231 140527580358400 _internal.py:97] Error on request:
Traceback (most recent call last):
  File "/media/ntu/volume1/home/s124md303_06/.local/lib/python3.8/site-packages/werkzeug/serving.py", line 370, in run_wsgi
    execute(self.server.app)
  File "/media/ntu/volume1/home/s124md303_06/.local/lib/python3.8/site-packages/werkzeug/serving.py", line 331, in execute
    application_iter = app(environ, start_response)
  File "/media/ntu/volume1/home/s124md303_06/.local/lib/python3.8/site-packages/tensorboard/backend/application.py", line 528, in __call__
    return self._app(environ, start_response)
  File "/media/ntu/volume1/home/s124md303_06/.local/lib/python3.8/site-packages/tensorboard/backend/application.py", line 569, in wrapper
    return wsgi_app(environ, start_response)
  File "/media/ntu/volume1/home/s124md303_06/.local/lib/python3.8/site-packages/tensorboard/backend/security_validator.py", line 91, in __call__
    return self._application(environ, start_response_proxy)
  File "/media/ntu/volume1/home/s124md303_06/.local/lib/python3.8/site-packages/tensorboard/backend/path_prefix.py", line 68, in __call__
    return self._application(environ, start_response)
  File "/media/ntu/volume1/home/s124md303_06/.local/lib/python3.8/site-packages/tensorboard/backend/experiment_id.py", line 73, in __call__
    return self._application(environ, start_response)
  File "/media/ntu/volume1/home/s124md303_06/.local/lib/python3.8/site-packages/tensorboard/backend/empty_path_redirect.py", line 43, in __call__
    return self._application(environ, start_response)
  File "/media/ntu/volume1/home/s124md303_06/.local/lib/python3.8/site-packages/tensorboard/backend/client_feature_flags.py", line 55, in __call__
    return self._application(environ, start_response)
  File "/media/ntu/volume1/home/s124md303_06/.local/lib/python3.8/site-packages/tensorboard/backend/auth_context_middleware.py", line 38, in __call__
    return self._application(environ, start_response)
  File "/media/ntu/volume1/home/s124md303_06/.local/lib/python3.8/site-packages/tensorboard/backend/application.py", line 551, in _route_request
    return self.exact_routes[clean_path](environ, start_response)
  File "/media/ntu/volume1/home/s124md303_06/.local/lib/python3.8/site-packages/werkzeug/wrappers/request.py", line 190, in application
    resp = f(*args[:-2] + (request,))
  File "/media/ntu/volume1/home/s124md303_06/.local/lib/python3.8/site-packages/tensorboard/plugins/hparams/hparams_plugin.py", line 122, in get_experiment_route
    json_format.MessageToJson(
TypeError: MessageToJson() got an unexpected keyword argument 'including_default_value_fields'
E0309 14:31:58.545289 140527320807168 _internal.py:97] Error on request:
Traceback (most recent call last):
  File "/media/ntu/volume1/home/s124md303_06/.local/lib/python3.8/site-packages/werkzeug/serving.py", line 370, in run_wsgi
    execute(self.server.app)
  File "/media/ntu/volume1/home/s124md303_06/.local/lib/python3.8/site-packages/werkzeug/serving.py", line 331, in execute
    application_iter = app(environ, start_response)
  File "/media/ntu/volume1/home/s124md303_06/.local/lib/python3.8/site-packages/tensorboard/backend/application.py", line 528, in __call__
    return self._app(environ, start_response)
  File "/media/ntu/volume1/home/s124md303_06/.local/lib/python3.8/site-packages/tensorboard/backend/application.py", line 569, in wrapper
    return wsgi_app(environ, start_response)
  File "/media/ntu/volume1/home/s124md303_06/.local/lib/python3.8/site-packages/tensorboard/backend/security_validator.py", line 91, in __call__
    return self._application(environ, start_response_proxy)
  File "/media/ntu/volume1/home/s124md303_06/.local/lib/python3.8/site-packages/tensorboard/backend/path_prefix.py", line 68, in __call__
    return self._application(environ, start_response)
  File "/media/ntu/volume1/home/s124md303_06/.local/lib/python3.8/site-packages/tensorboard/backend/experiment_id.py", line 73, in __call__
    return self._application(environ, start_response)
  File "/media/ntu/volume1/home/s124md303_06/.local/lib/python3.8/site-packages/tensorboard/backend/empty_path_redirect.py", line 43, in __call__
    return self._application(environ, start_response)
  File "/media/ntu/volume1/home/s124md303_06/.local/lib/python3.8/site-packages/tensorboard/backend/client_feature_flags.py", line 55, in __call__
    return self._application(environ, start_response)
  File "/media/ntu/volume1/home/s124md303_06/.local/lib/python3.8/site-packages/tensorboard/backend/auth_context_middleware.py", line 38, in __call__
    return self._application(environ, start_response)
  File "/media/ntu/volume1/home/s124md303_06/.local/lib/python3.8/site-packages/tensorboard/backend/application.py", line 551, in _route_request
    return self.exact_routes[clean_path](environ, start_response)
  File "/media/ntu/volume1/home/s124md303_06/.local/lib/python3.8/site-packages/werkzeug/wrappers/request.py", line 190, in application
    resp = f(*args[:-2] + (request,))
  File "/media/ntu/volume1/home/s124md303_06/.local/lib/python3.8/site-packages/tensorboard/plugins/hparams/hparams_plugin.py", line 122, in get_experiment_route
    json_format.MessageToJson(
TypeError: MessageToJson() got an unexpected keyword argument 'including_default_value_fields'
E0309 14:32:28.548457 140527580358400 _internal.py:97] Error on request:
Traceback (most recent call last):
  File "/media/ntu/volume1/home/s124md303_06/.local/lib/python3.8/site-packages/werkzeug/serving.py", line 370, in run_wsgi
    execute(self.server.app)
  File "/media/ntu/volume1/home/s124md303_06/.local/lib/python3.8/site-packages/werkzeug/serving.py", line 331, in execute
    application_iter = app(environ, start_response)
  File "/media/ntu/volume1/home/s124md303_06/.local/lib/python3.8/site-packages/tensorboard/backend/application.py", line 528, in __call__
    return self._app(environ, start_response)
  File "/media/ntu/volume1/home/s124md303_06/.local/lib/python3.8/site-packages/tensorboard/backend/application.py", line 569, in wrapper
    return wsgi_app(environ, start_response)
  File "/media/ntu/volume1/home/s124md303_06/.local/lib/python3.8/site-packages/tensorboard/backend/security_validator.py", line 91, in __call__
    return self._application(environ, start_response_proxy)
  File "/media/ntu/volume1/home/s124md303_06/.local/lib/python3.8/site-packages/tensorboard/backend/path_prefix.py", line 68, in __call__
    return self._application(environ, start_response)
  File "/media/ntu/volume1/home/s124md303_06/.local/lib/python3.8/site-packages/tensorboard/backend/experiment_id.py", line 73, in __call__
    return self._application(environ, start_response)
  File "/media/ntu/volume1/home/s124md303_06/.local/lib/python3.8/site-packages/tensorboard/backend/empty_path_redirect.py", line 43, in __call__
    return self._application(environ, start_response)
  File "/media/ntu/volume1/home/s124md303_06/.local/lib/python3.8/site-packages/tensorboard/backend/client_feature_flags.py", line 55, in __call__
    return self._application(environ, start_response)
  File "/media/ntu/volume1/home/s124md303_06/.local/lib/python3.8/site-packages/tensorboard/backend/auth_context_middleware.py", line 38, in __call__
    return self._application(environ, start_response)
  File "/media/ntu/volume1/home/s124md303_06/.local/lib/python3.8/site-packages/tensorboard/backend/application.py", line 551, in _route_request
    return self.exact_routes[clean_path](environ, start_response)
  File "/media/ntu/volume1/home/s124md303_06/.local/lib/python3.8/site-packages/werkzeug/wrappers/request.py", line 190, in application
    resp = f(*args[:-2] + (request,))
  File "/media/ntu/volume1/home/s124md303_06/.local/lib/python3.8/site-packages/tensorboard/plugins/hparams/hparams_plugin.py", line 122, in get_experiment_route
    json_format.MessageToJson(
TypeError: MessageToJson() got an unexpected keyword argument 'including_default_value_fields'
E0309 14:32:39.384209 140527404701440 _internal.py:97] Error on request:
Traceback (most recent call last):
  File "/media/ntu/volume1/home/s124md303_06/.local/lib/python3.8/site-packages/werkzeug/serving.py", line 370, in run_wsgi
    execute(self.server.app)
  File "/media/ntu/volume1/home/s124md303_06/.local/lib/python3.8/site-packages/werkzeug/serving.py", line 331, in execute
    application_iter = app(environ, start_response)
  File "/media/ntu/volume1/home/s124md303_06/.local/lib/python3.8/site-packages/tensorboard/backend/application.py", line 528, in __call__
    return self._app(environ, start_response)
  File "/media/ntu/volume1/home/s124md303_06/.local/lib/python3.8/site-packages/tensorboard/backend/application.py", line 569, in wrapper
    return wsgi_app(environ, start_response)
  File "/media/ntu/volume1/home/s124md303_06/.local/lib/python3.8/site-packages/tensorboard/backend/security_validator.py", line 91, in __call__
    return self._application(environ, start_response_proxy)
  File "/media/ntu/volume1/home/s124md303_06/.local/lib/python3.8/site-packages/tensorboard/backend/path_prefix.py", line 68, in __call__
    return self._application(environ, start_response)
  File "/media/ntu/volume1/home/s124md303_06/.local/lib/python3.8/site-packages/tensorboard/backend/experiment_id.py", line 73, in __call__
    return self._application(environ, start_response)
  File "/media/ntu/volume1/home/s124md303_06/.local/lib/python3.8/site-packages/tensorboard/backend/empty_path_redirect.py", line 43, in __call__
    return self._application(environ, start_response)
  File "/media/ntu/volume1/home/s124md303_06/.local/lib/python3.8/site-packages/tensorboard/backend/client_feature_flags.py", line 55, in __call__
    return self._application(environ, start_response)
  File "/media/ntu/volume1/home/s124md303_06/.local/lib/python3.8/site-packages/tensorboard/backend/auth_context_middleware.py", line 38, in __call__
    return self._application(environ, start_response)
  File "/media/ntu/volume1/home/s124md303_06/.local/lib/python3.8/site-packages/tensorboard/backend/application.py", line 551, in _route_request
    return self.exact_routes[clean_path](environ, start_response)
  File "/media/ntu/volume1/home/s124md303_06/.local/lib/python3.8/site-packages/werkzeug/wrappers/request.py", line 190, in application
    resp = f(*args[:-2] + (request,))
  File "/media/ntu/volume1/home/s124md303_06/.local/lib/python3.8/site-packages/tensorboard/plugins/hparams/hparams_plugin.py", line 122, in get_experiment_route
    json_format.MessageToJson(
TypeError: MessageToJson() got an unexpected keyword argument 'including_default_value_fields'
E0309 14:32:39.489690 140527530542848 _internal.py:97] Error on request:
Traceback (most recent call last):
  File "/media/ntu/volume1/home/s124md303_06/.local/lib/python3.8/site-packages/werkzeug/serving.py", line 370, in run_wsgi
    execute(self.server.app)
  File "/media/ntu/volume1/home/s124md303_06/.local/lib/python3.8/site-packages/werkzeug/serving.py", line 331, in execute
    application_iter = app(environ, start_response)
  File "/media/ntu/volume1/home/s124md303_06/.local/lib/python3.8/site-packages/tensorboard/backend/application.py", line 528, in __call__
    return self._app(environ, start_response)
  File "/media/ntu/volume1/home/s124md303_06/.local/lib/python3.8/site-packages/tensorboard/backend/application.py", line 569, in wrapper
    return wsgi_app(environ, start_response)
  File "/media/ntu/volume1/home/s124md303_06/.local/lib/python3.8/site-packages/tensorboard/backend/security_validator.py", line 91, in __call__
    return self._application(environ, start_response_proxy)
  File "/media/ntu/volume1/home/s124md303_06/.local/lib/python3.8/site-packages/tensorboard/backend/path_prefix.py", line 68, in __call__
    return self._application(environ, start_response)
  File "/media/ntu/volume1/home/s124md303_06/.local/lib/python3.8/site-packages/tensorboard/backend/experiment_id.py", line 73, in __call__
    return self._application(environ, start_response)
  File "/media/ntu/volume1/home/s124md303_06/.local/lib/python3.8/site-packages/tensorboard/backend/empty_path_redirect.py", line 43, in __call__
    return self._application(environ, start_response)
  File "/media/ntu/volume1/home/s124md303_06/.local/lib/python3.8/site-packages/tensorboard/backend/client_feature_flags.py", line 55, in __call__
    return self._application(environ, start_response)
  File "/media/ntu/volume1/home/s124md303_06/.local/lib/python3.8/site-packages/tensorboard/backend/auth_context_middleware.py", line 38, in __call__
    return self._application(environ, start_response)
  File "/media/ntu/volume1/home/s124md303_06/.local/lib/python3.8/site-packages/tensorboard/backend/application.py", line 551, in _route_request
    return self.exact_routes[clean_path](environ, start_response)
  File "/media/ntu/volume1/home/s124md303_06/.local/lib/python3.8/site-packages/werkzeug/wrappers/request.py", line 190, in application
    resp = f(*args[:-2] + (request,))
  File "/media/ntu/volume1/home/s124md303_06/.local/lib/python3.8/site-packages/tensorboard/plugins/hparams/hparams_plugin.py", line 122, in get_experiment_route
    json_format.MessageToJson(
TypeError: MessageToJson() got an unexpected keyword argument 'including_default_value_fields'
E0309 14:32:41.651052 140527320807168 _internal.py:97] Error on request:
Traceback (most recent call last):
  File "/media/ntu/volume1/home/s124md303_06/.local/lib/python3.8/site-packages/werkzeug/serving.py", line 370, in run_wsgi
    execute(self.server.app)
  File "/media/ntu/volume1/home/s124md303_06/.local/lib/python3.8/site-packages/werkzeug/serving.py", line 331, in execute
    application_iter = app(environ, start_response)
  File "/media/ntu/volume1/home/s124md303_06/.local/lib/python3.8/site-packages/tensorboard/backend/application.py", line 528, in __call__
    return self._app(environ, start_response)
  File "/media/ntu/volume1/home/s124md303_06/.local/lib/python3.8/site-packages/tensorboard/backend/application.py", line 569, in wrapper
    return wsgi_app(environ, start_response)
  File "/media/ntu/volume1/home/s124md303_06/.local/lib/python3.8/site-packages/tensorboard/backend/security_validator.py", line 91, in __call__
    return self._application(environ, start_response_proxy)
  File "/media/ntu/volume1/home/s124md303_06/.local/lib/python3.8/site-packages/tensorboard/backend/path_prefix.py", line 68, in __call__
    return self._application(environ, start_response)
  File "/media/ntu/volume1/home/s124md303_06/.local/lib/python3.8/site-packages/tensorboard/backend/experiment_id.py", line 73, in __call__
    return self._application(environ, start_response)
  File "/media/ntu/volume1/home/s124md303_06/.local/lib/python3.8/site-packages/tensorboard/backend/empty_path_redirect.py", line 43, in __call__
    return self._application(environ, start_response)
  File "/media/ntu/volume1/home/s124md303_06/.local/lib/python3.8/site-packages/tensorboard/backend/client_feature_flags.py", line 55, in __call__
    return self._application(environ, start_response)
  File "/media/ntu/volume1/home/s124md303_06/.local/lib/python3.8/site-packages/tensorboard/backend/auth_context_middleware.py", line 38, in __call__
    return self._application(environ, start_response)
  File "/media/ntu/volume1/home/s124md303_06/.local/lib/python3.8/site-packages/tensorboard/backend/application.py", line 551, in _route_request
    return self.exact_routes[clean_path](environ, start_response)
  File "/media/ntu/volume1/home/s124md303_06/.local/lib/python3.8/site-packages/werkzeug/wrappers/request.py", line 190, in application
    resp = f(*args[:-2] + (request,))
  File "/media/ntu/volume1/home/s124md303_06/.local/lib/python3.8/site-packages/tensorboard/plugins/hparams/hparams_plugin.py", line 122, in get_experiment_route
    json_format.MessageToJson(
TypeError: MessageToJson() got an unexpected keyword argument 'including_default_value_fields'
E0309 14:32:41.765921 140527320807168 _internal.py:97] Error on request:
Traceback (most recent call last):
  File "/media/ntu/volume1/home/s124md303_06/.local/lib/python3.8/site-packages/werkzeug/serving.py", line 370, in run_wsgi
    execute(self.server.app)
  File "/media/ntu/volume1/home/s124md303_06/.local/lib/python3.8/site-packages/werkzeug/serving.py", line 331, in execute
    application_iter = app(environ, start_response)
  File "/media/ntu/volume1/home/s124md303_06/.local/lib/python3.8/site-packages/tensorboard/backend/application.py", line 528, in __call__
    return self._app(environ, start_response)
  File "/media/ntu/volume1/home/s124md303_06/.local/lib/python3.8/site-packages/tensorboard/backend/application.py", line 569, in wrapper
    return wsgi_app(environ, start_response)
  File "/media/ntu/volume1/home/s124md303_06/.local/lib/python3.8/site-packages/tensorboard/backend/security_validator.py", line 91, in __call__
    return self._application(environ, start_response_proxy)
  File "/media/ntu/volume1/home/s124md303_06/.local/lib/python3.8/site-packages/tensorboard/backend/path_prefix.py", line 68, in __call__
    return self._application(environ, start_response)
  File "/media/ntu/volume1/home/s124md303_06/.local/lib/python3.8/site-packages/tensorboard/backend/experiment_id.py", line 73, in __call__
    return self._application(environ, start_response)
  File "/media/ntu/volume1/home/s124md303_06/.local/lib/python3.8/site-packages/tensorboard/backend/empty_path_redirect.py", line 43, in __call__
    return self._application(environ, start_response)
  File "/media/ntu/volume1/home/s124md303_06/.local/lib/python3.8/site-packages/tensorboard/backend/client_feature_flags.py", line 55, in __call__
    return self._application(environ, start_response)
  File "/media/ntu/volume1/home/s124md303_06/.local/lib/python3.8/site-packages/tensorboard/backend/auth_context_middleware.py", line 38, in __call__
    return self._application(environ, start_response)
  File "/media/ntu/volume1/home/s124md303_06/.local/lib/python3.8/site-packages/tensorboard/backend/application.py", line 551, in _route_request
    return self.exact_routes[clean_path](environ, start_response)
  File "/media/ntu/volume1/home/s124md303_06/.local/lib/python3.8/site-packages/werkzeug/wrappers/request.py", line 190, in application
    resp = f(*args[:-2] + (request,))
  File "/media/ntu/volume1/home/s124md303_06/.local/lib/python3.8/site-packages/tensorboard/plugins/hparams/hparams_plugin.py", line 122, in get_experiment_route
    json_format.MessageToJson(
TypeError: MessageToJson() got an unexpected keyword argument 'including_default_value_fields'
E0309 14:33:11.666383 140527530542848 _internal.py:97] Error on request:
Traceback (most recent call last):
  File "/media/ntu/volume1/home/s124md303_06/.local/lib/python3.8/site-packages/werkzeug/serving.py", line 370, in run_wsgi
    execute(self.server.app)
  File "/media/ntu/volume1/home/s124md303_06/.local/lib/python3.8/site-packages/werkzeug/serving.py", line 331, in execute
    application_iter = app(environ, start_response)
  File "/media/ntu/volume1/home/s124md303_06/.local/lib/python3.8/site-packages/tensorboard/backend/application.py", line 528, in __call__
    return self._app(environ, start_response)
  File "/media/ntu/volume1/home/s124md303_06/.local/lib/python3.8/site-packages/tensorboard/backend/application.py", line 569, in wrapper
    return wsgi_app(environ, start_response)
  File "/media/ntu/volume1/home/s124md303_06/.local/lib/python3.8/site-packages/tensorboard/backend/security_validator.py", line 91, in __call__
    return self._application(environ, start_response_proxy)
  File "/media/ntu/volume1/home/s124md303_06/.local/lib/python3.8/site-packages/tensorboard/backend/path_prefix.py", line 68, in __call__
    return self._application(environ, start_response)
  File "/media/ntu/volume1/home/s124md303_06/.local/lib/python3.8/site-packages/tensorboard/backend/experiment_id.py", line 73, in __call__
    return self._application(environ, start_response)
  File "/media/ntu/volume1/home/s124md303_06/.local/lib/python3.8/site-packages/tensorboard/backend/empty_path_redirect.py", line 43, in __call__
    return self._application(environ, start_response)
  File "/media/ntu/volume1/home/s124md303_06/.local/lib/python3.8/site-packages/tensorboard/backend/client_feature_flags.py", line 55, in __call__
    return self._application(environ, start_response)
  File "/media/ntu/volume1/home/s124md303_06/.local/lib/python3.8/site-packages/tensorboard/backend/auth_context_middleware.py", line 38, in __call__
    return self._application(environ, start_response)
  File "/media/ntu/volume1/home/s124md303_06/.local/lib/python3.8/site-packages/tensorboard/backend/application.py", line 551, in _route_request
    return self.exact_routes[clean_path](environ, start_response)
  File "/media/ntu/volume1/home/s124md303_06/.local/lib/python3.8/site-packages/werkzeug/wrappers/request.py", line 190, in application
    resp = f(*args[:-2] + (request,))
  File "/media/ntu/volume1/home/s124md303_06/.local/lib/python3.8/site-packages/tensorboard/plugins/hparams/hparams_plugin.py", line 122, in get_experiment_route
    json_format.MessageToJson(
TypeError: MessageToJson() got an unexpected keyword argument 'including_default_value_fields'
E0309 14:33:41.681729 140527446648576 _internal.py:97] Error on request:
Traceback (most recent call last):
  File "/media/ntu/volume1/home/s124md303_06/.local/lib/python3.8/site-packages/werkzeug/serving.py", line 370, in run_wsgi
    execute(self.server.app)
  File "/media/ntu/volume1/home/s124md303_06/.local/lib/python3.8/site-packages/werkzeug/serving.py", line 331, in execute
    application_iter = app(environ, start_response)
  File "/media/ntu/volume1/home/s124md303_06/.local/lib/python3.8/site-packages/tensorboard/backend/application.py", line 528, in __call__
    return self._app(environ, start_response)
  File "/media/ntu/volume1/home/s124md303_06/.local/lib/python3.8/site-packages/tensorboard/backend/application.py", line 569, in wrapper
    return wsgi_app(environ, start_response)
  File "/media/ntu/volume1/home/s124md303_06/.local/lib/python3.8/site-packages/tensorboard/backend/security_validator.py", line 91, in __call__
    return self._application(environ, start_response_proxy)
  File "/media/ntu/volume1/home/s124md303_06/.local/lib/python3.8/site-packages/tensorboard/backend/path_prefix.py", line 68, in __call__
    return self._application(environ, start_response)
  File "/media/ntu/volume1/home/s124md303_06/.local/lib/python3.8/site-packages/tensorboard/backend/experiment_id.py", line 73, in __call__
    return self._application(environ, start_response)
  File "/media/ntu/volume1/home/s124md303_06/.local/lib/python3.8/site-packages/tensorboard/backend/empty_path_redirect.py", line 43, in __call__
    return self._application(environ, start_response)
  File "/media/ntu/volume1/home/s124md303_06/.local/lib/python3.8/site-packages/tensorboard/backend/client_feature_flags.py", line 55, in __call__
    return self._application(environ, start_response)
  File "/media/ntu/volume1/home/s124md303_06/.local/lib/python3.8/site-packages/tensorboard/backend/auth_context_middleware.py", line 38, in __call__
    return self._application(environ, start_response)
  File "/media/ntu/volume1/home/s124md303_06/.local/lib/python3.8/site-packages/tensorboard/backend/application.py", line 551, in _route_request
    return self.exact_routes[clean_path](environ, start_response)
  File "/media/ntu/volume1/home/s124md303_06/.local/lib/python3.8/site-packages/werkzeug/wrappers/request.py", line 190, in application
    resp = f(*args[:-2] + (request,))
  File "/media/ntu/volume1/home/s124md303_06/.local/lib/python3.8/site-packages/tensorboard/plugins/hparams/hparams_plugin.py", line 122, in get_experiment_route
    json_format.MessageToJson(
TypeError: MessageToJson() got an unexpected keyword argument 'including_default_value_fields'
E0309 14:34:11.696084 140527530542848 _internal.py:97] Error on request:
Traceback (most recent call last):
  File "/media/ntu/volume1/home/s124md303_06/.local/lib/python3.8/site-packages/werkzeug/serving.py", line 370, in run_wsgi
    execute(self.server.app)
  File "/media/ntu/volume1/home/s124md303_06/.local/lib/python3.8/site-packages/werkzeug/serving.py", line 331, in execute
    application_iter = app(environ, start_response)
  File "/media/ntu/volume1/home/s124md303_06/.local/lib/python3.8/site-packages/tensorboard/backend/application.py", line 528, in __call__
    return self._app(environ, start_response)
  File "/media/ntu/volume1/home/s124md303_06/.local/lib/python3.8/site-packages/tensorboard/backend/application.py", line 569, in wrapper
    return wsgi_app(environ, start_response)
  File "/media/ntu/volume1/home/s124md303_06/.local/lib/python3.8/site-packages/tensorboard/backend/security_validator.py", line 91, in __call__
    return self._application(environ, start_response_proxy)
  File "/media/ntu/volume1/home/s124md303_06/.local/lib/python3.8/site-packages/tensorboard/backend/path_prefix.py", line 68, in __call__
    return self._application(environ, start_response)
  File "/media/ntu/volume1/home/s124md303_06/.local/lib/python3.8/site-packages/tensorboard/backend/experiment_id.py", line 73, in __call__
    return self._application(environ, start_response)
  File "/media/ntu/volume1/home/s124md303_06/.local/lib/python3.8/site-packages/tensorboard/backend/empty_path_redirect.py", line 43, in __call__
    return self._application(environ, start_response)
  File "/media/ntu/volume1/home/s124md303_06/.local/lib/python3.8/site-packages/tensorboard/backend/client_feature_flags.py", line 55, in __call__
    return self._application(environ, start_response)
  File "/media/ntu/volume1/home/s124md303_06/.local/lib/python3.8/site-packages/tensorboard/backend/auth_context_middleware.py", line 38, in __call__
    return self._application(environ, start_response)
  File "/media/ntu/volume1/home/s124md303_06/.local/lib/python3.8/site-packages/tensorboard/backend/application.py", line 551, in _route_request
    return self.exact_routes[clean_path](environ, start_response)
  File "/media/ntu/volume1/home/s124md303_06/.local/lib/python3.8/site-packages/werkzeug/wrappers/request.py", line 190, in application
    resp = f(*args[:-2] + (request,))
  File "/media/ntu/volume1/home/s124md303_06/.local/lib/python3.8/site-packages/tensorboard/plugins/hparams/hparams_plugin.py", line 122, in get_experiment_route
    json_format.MessageToJson(
TypeError: MessageToJson() got an unexpected keyword argument 'including_default_value_fields'
E0309 14:34:41.700341 140527580358400 _internal.py:97] Error on request:
Traceback (most recent call last):
  File "/media/ntu/volume1/home/s124md303_06/.local/lib/python3.8/site-packages/werkzeug/serving.py", line 370, in run_wsgi
    execute(self.server.app)
  File "/media/ntu/volume1/home/s124md303_06/.local/lib/python3.8/site-packages/werkzeug/serving.py", line 331, in execute
    application_iter = app(environ, start_response)
  File "/media/ntu/volume1/home/s124md303_06/.local/lib/python3.8/site-packages/tensorboard/backend/application.py", line 528, in __call__
    return self._app(environ, start_response)
  File "/media/ntu/volume1/home/s124md303_06/.local/lib/python3.8/site-packages/tensorboard/backend/application.py", line 569, in wrapper
    return wsgi_app(environ, start_response)
  File "/media/ntu/volume1/home/s124md303_06/.local/lib/python3.8/site-packages/tensorboard/backend/security_validator.py", line 91, in __call__
    return self._application(environ, start_response_proxy)
  File "/media/ntu/volume1/home/s124md303_06/.local/lib/python3.8/site-packages/tensorboard/backend/path_prefix.py", line 68, in __call__
    return self._application(environ, start_response)
  File "/media/ntu/volume1/home/s124md303_06/.local/lib/python3.8/site-packages/tensorboard/backend/experiment_id.py", line 73, in __call__
    return self._application(environ, start_response)
  File "/media/ntu/volume1/home/s124md303_06/.local/lib/python3.8/site-packages/tensorboard/backend/empty_path_redirect.py", line 43, in __call__
    return self._application(environ, start_response)
  File "/media/ntu/volume1/home/s124md303_06/.local/lib/python3.8/site-packages/tensorboard/backend/client_feature_flags.py", line 55, in __call__
    return self._application(environ, start_response)
  File "/media/ntu/volume1/home/s124md303_06/.local/lib/python3.8/site-packages/tensorboard/backend/auth_context_middleware.py", line 38, in __call__
    return self._application(environ, start_response)
  File "/media/ntu/volume1/home/s124md303_06/.local/lib/python3.8/site-packages/tensorboard/backend/application.py", line 551, in _route_request
    return self.exact_routes[clean_path](environ, start_response)
  File "/media/ntu/volume1/home/s124md303_06/.local/lib/python3.8/site-packages/werkzeug/wrappers/request.py", line 190, in application
    resp = f(*args[:-2] + (request,))
  File "/media/ntu/volume1/home/s124md303_06/.local/lib/python3.8/site-packages/tensorboard/plugins/hparams/hparams_plugin.py", line 122, in get_experiment_route
    json_format.MessageToJson(
TypeError: MessageToJson() got an unexpected keyword argument 'including_default_value_fields'
E0309 14:35:11.706728 140527580358400 _internal.py:97] Error on request:
Traceback (most recent call last):
  File "/media/ntu/volume1/home/s124md303_06/.local/lib/python3.8/site-packages/werkzeug/serving.py", line 370, in run_wsgi
    execute(self.server.app)
  File "/media/ntu/volume1/home/s124md303_06/.local/lib/python3.8/site-packages/werkzeug/serving.py", line 331, in execute
    application_iter = app(environ, start_response)
  File "/media/ntu/volume1/home/s124md303_06/.local/lib/python3.8/site-packages/tensorboard/backend/application.py", line 528, in __call__
    return self._app(environ, start_response)
  File "/media/ntu/volume1/home/s124md303_06/.local/lib/python3.8/site-packages/tensorboard/backend/application.py", line 569, in wrapper
    return wsgi_app(environ, start_response)
  File "/media/ntu/volume1/home/s124md303_06/.local/lib/python3.8/site-packages/tensorboard/backend/security_validator.py", line 91, in __call__
    return self._application(environ, start_response_proxy)
  File "/media/ntu/volume1/home/s124md303_06/.local/lib/python3.8/site-packages/tensorboard/backend/path_prefix.py", line 68, in __call__
    return self._application(environ, start_response)
  File "/media/ntu/volume1/home/s124md303_06/.local/lib/python3.8/site-packages/tensorboard/backend/experiment_id.py", line 73, in __call__
    return self._application(environ, start_response)
  File "/media/ntu/volume1/home/s124md303_06/.local/lib/python3.8/site-packages/tensorboard/backend/empty_path_redirect.py", line 43, in __call__
    return self._application(environ, start_response)
  File "/media/ntu/volume1/home/s124md303_06/.local/lib/python3.8/site-packages/tensorboard/backend/client_feature_flags.py", line 55, in __call__
    return self._application(environ, start_response)
  File "/media/ntu/volume1/home/s124md303_06/.local/lib/python3.8/site-packages/tensorboard/backend/auth_context_middleware.py", line 38, in __call__
    return self._application(environ, start_response)
  File "/media/ntu/volume1/home/s124md303_06/.local/lib/python3.8/site-packages/tensorboard/backend/application.py", line 551, in _route_request
    return self.exact_routes[clean_path](environ, start_response)
  File "/media/ntu/volume1/home/s124md303_06/.local/lib/python3.8/site-packages/werkzeug/wrappers/request.py", line 190, in application
    resp = f(*args[:-2] + (request,))
  File "/media/ntu/volume1/home/s124md303_06/.local/lib/python3.8/site-packages/tensorboard/plugins/hparams/hparams_plugin.py", line 122, in get_experiment_route
    json_format.MessageToJson(
TypeError: MessageToJson() got an unexpected keyword argument 'including_default_value_fields'
E0309 14:35:20.355723 140527446648576 _internal.py:97] Error on request:
Traceback (most recent call last):
  File "/media/ntu/volume1/home/s124md303_06/.local/lib/python3.8/site-packages/werkzeug/serving.py", line 370, in run_wsgi
    execute(self.server.app)
  File "/media/ntu/volume1/home/s124md303_06/.local/lib/python3.8/site-packages/werkzeug/serving.py", line 331, in execute
    application_iter = app(environ, start_response)
  File "/media/ntu/volume1/home/s124md303_06/.local/lib/python3.8/site-packages/tensorboard/backend/application.py", line 528, in __call__
    return self._app(environ, start_response)
  File "/media/ntu/volume1/home/s124md303_06/.local/lib/python3.8/site-packages/tensorboard/backend/application.py", line 569, in wrapper
    return wsgi_app(environ, start_response)
  File "/media/ntu/volume1/home/s124md303_06/.local/lib/python3.8/site-packages/tensorboard/backend/security_validator.py", line 91, in __call__
    return self._application(environ, start_response_proxy)
  File "/media/ntu/volume1/home/s124md303_06/.local/lib/python3.8/site-packages/tensorboard/backend/path_prefix.py", line 68, in __call__
    return self._application(environ, start_response)
  File "/media/ntu/volume1/home/s124md303_06/.local/lib/python3.8/site-packages/tensorboard/backend/experiment_id.py", line 73, in __call__
    return self._application(environ, start_response)
  File "/media/ntu/volume1/home/s124md303_06/.local/lib/python3.8/site-packages/tensorboard/backend/empty_path_redirect.py", line 43, in __call__
    return self._application(environ, start_response)
  File "/media/ntu/volume1/home/s124md303_06/.local/lib/python3.8/site-packages/tensorboard/backend/client_feature_flags.py", line 55, in __call__
    return self._application(environ, start_response)
  File "/media/ntu/volume1/home/s124md303_06/.local/lib/python3.8/site-packages/tensorboard/backend/auth_context_middleware.py", line 38, in __call__
    return self._application(environ, start_response)
  File "/media/ntu/volume1/home/s124md303_06/.local/lib/python3.8/site-packages/tensorboard/backend/application.py", line 551, in _route_request
    return self.exact_routes[clean_path](environ, start_response)
  File "/media/ntu/volume1/home/s124md303_06/.local/lib/python3.8/site-packages/werkzeug/wrappers/request.py", line 190, in application
    resp = f(*args[:-2] + (request,))
  File "/media/ntu/volume1/home/s124md303_06/.local/lib/python3.8/site-packages/tensorboard/plugins/hparams/hparams_plugin.py", line 122, in get_experiment_route
    json_format.MessageToJson(
TypeError: MessageToJson() got an unexpected keyword argument 'including_default_value_fields'
E0309 14:35:20.466095 140527530542848 _internal.py:97] Error on request:
Traceback (most recent call last):
  File "/media/ntu/volume1/home/s124md303_06/.local/lib/python3.8/site-packages/werkzeug/serving.py", line 370, in run_wsgi
    execute(self.server.app)
  File "/media/ntu/volume1/home/s124md303_06/.local/lib/python3.8/site-packages/werkzeug/serving.py", line 331, in execute
    application_iter = app(environ, start_response)
  File "/media/ntu/volume1/home/s124md303_06/.local/lib/python3.8/site-packages/tensorboard/backend/application.py", line 528, in __call__
    return self._app(environ, start_response)
  File "/media/ntu/volume1/home/s124md303_06/.local/lib/python3.8/site-packages/tensorboard/backend/application.py", line 569, in wrapper
    return wsgi_app(environ, start_response)
  File "/media/ntu/volume1/home/s124md303_06/.local/lib/python3.8/site-packages/tensorboard/backend/security_validator.py", line 91, in __call__
    return self._application(environ, start_response_proxy)
  File "/media/ntu/volume1/home/s124md303_06/.local/lib/python3.8/site-packages/tensorboard/backend/path_prefix.py", line 68, in __call__
    return self._application(environ, start_response)
  File "/media/ntu/volume1/home/s124md303_06/.local/lib/python3.8/site-packages/tensorboard/backend/experiment_id.py", line 73, in __call__
    return self._application(environ, start_response)
  File "/media/ntu/volume1/home/s124md303_06/.local/lib/python3.8/site-packages/tensorboard/backend/empty_path_redirect.py", line 43, in __call__
    return self._application(environ, start_response)
  File "/media/ntu/volume1/home/s124md303_06/.local/lib/python3.8/site-packages/tensorboard/backend/client_feature_flags.py", line 55, in __call__
    return self._application(environ, start_response)
  File "/media/ntu/volume1/home/s124md303_06/.local/lib/python3.8/site-packages/tensorboard/backend/auth_context_middleware.py", line 38, in __call__
    return self._application(environ, start_response)
  File "/media/ntu/volume1/home/s124md303_06/.local/lib/python3.8/site-packages/tensorboard/backend/application.py", line 551, in _route_request
    return self.exact_routes[clean_path](environ, start_response)
  File "/media/ntu/volume1/home/s124md303_06/.local/lib/python3.8/site-packages/werkzeug/wrappers/request.py", line 190, in application
    resp = f(*args[:-2] + (request,))
  File "/media/ntu/volume1/home/s124md303_06/.local/lib/python3.8/site-packages/tensorboard/plugins/hparams/hparams_plugin.py", line 122, in get_experiment_route
    json_format.MessageToJson(
TypeError: MessageToJson() got an unexpected keyword argument 'including_default_value_fields'
E0309 14:35:21.867518 140527404701440 _internal.py:97] Error on request:
Traceback (most recent call last):
  File "/media/ntu/volume1/home/s124md303_06/.local/lib/python3.8/site-packages/werkzeug/serving.py", line 370, in run_wsgi
    execute(self.server.app)
  File "/media/ntu/volume1/home/s124md303_06/.local/lib/python3.8/site-packages/werkzeug/serving.py", line 331, in execute
    application_iter = app(environ, start_response)
  File "/media/ntu/volume1/home/s124md303_06/.local/lib/python3.8/site-packages/tensorboard/backend/application.py", line 528, in __call__
    return self._app(environ, start_response)
  File "/media/ntu/volume1/home/s124md303_06/.local/lib/python3.8/site-packages/tensorboard/backend/application.py", line 569, in wrapper
    return wsgi_app(environ, start_response)
  File "/media/ntu/volume1/home/s124md303_06/.local/lib/python3.8/site-packages/tensorboard/backend/security_validator.py", line 91, in __call__
    return self._application(environ, start_response_proxy)
  File "/media/ntu/volume1/home/s124md303_06/.local/lib/python3.8/site-packages/tensorboard/backend/path_prefix.py", line 68, in __call__
    return self._application(environ, start_response)
  File "/media/ntu/volume1/home/s124md303_06/.local/lib/python3.8/site-packages/tensorboard/backend/experiment_id.py", line 73, in __call__
    return self._application(environ, start_response)
  File "/media/ntu/volume1/home/s124md303_06/.local/lib/python3.8/site-packages/tensorboard/backend/empty_path_redirect.py", line 43, in __call__
    return self._application(environ, start_response)
  File "/media/ntu/volume1/home/s124md303_06/.local/lib/python3.8/site-packages/tensorboard/backend/client_feature_flags.py", line 55, in __call__
    return self._application(environ, start_response)
  File "/media/ntu/volume1/home/s124md303_06/.local/lib/python3.8/site-packages/tensorboard/backend/auth_context_middleware.py", line 38, in __call__
    return self._application(environ, start_response)
  File "/media/ntu/volume1/home/s124md303_06/.local/lib/python3.8/site-packages/tensorboard/backend/application.py", line 551, in _route_request
    return self.exact_routes[clean_path](environ, start_response)
  File "/media/ntu/volume1/home/s124md303_06/.local/lib/python3.8/site-packages/werkzeug/wrappers/request.py", line 190, in application
    resp = f(*args[:-2] + (request,))
  File "/media/ntu/volume1/home/s124md303_06/.local/lib/python3.8/site-packages/tensorboard/plugins/hparams/hparams_plugin.py", line 122, in get_experiment_route
    json_format.MessageToJson(
TypeError: MessageToJson() got an unexpected keyword argument 'including_default_value_fields'
E0309 14:35:21.989553 140527488595712 _internal.py:97] Error on request:
Traceback (most recent call last):
  File "/media/ntu/volume1/home/s124md303_06/.local/lib/python3.8/site-packages/werkzeug/serving.py", line 370, in run_wsgi
    execute(self.server.app)
  File "/media/ntu/volume1/home/s124md303_06/.local/lib/python3.8/site-packages/werkzeug/serving.py", line 331, in execute
    application_iter = app(environ, start_response)
  File "/media/ntu/volume1/home/s124md303_06/.local/lib/python3.8/site-packages/tensorboard/backend/application.py", line 528, in __call__
    return self._app(environ, start_response)
  File "/media/ntu/volume1/home/s124md303_06/.local/lib/python3.8/site-packages/tensorboard/backend/application.py", line 569, in wrapper
    return wsgi_app(environ, start_response)
  File "/media/ntu/volume1/home/s124md303_06/.local/lib/python3.8/site-packages/tensorboard/backend/security_validator.py", line 91, in __call__
    return self._application(environ, start_response_proxy)
  File "/media/ntu/volume1/home/s124md303_06/.local/lib/python3.8/site-packages/tensorboard/backend/path_prefix.py", line 68, in __call__
    return self._application(environ, start_response)
  File "/media/ntu/volume1/home/s124md303_06/.local/lib/python3.8/site-packages/tensorboard/backend/experiment_id.py", line 73, in __call__
    return self._application(environ, start_response)
  File "/media/ntu/volume1/home/s124md303_06/.local/lib/python3.8/site-packages/tensorboard/backend/empty_path_redirect.py", line 43, in __call__
    return self._application(environ, start_response)
  File "/media/ntu/volume1/home/s124md303_06/.local/lib/python3.8/site-packages/tensorboard/backend/client_feature_flags.py", line 55, in __call__
    return self._application(environ, start_response)
  File "/media/ntu/volume1/home/s124md303_06/.local/lib/python3.8/site-packages/tensorboard/backend/auth_context_middleware.py", line 38, in __call__
    return self._application(environ, start_response)
  File "/media/ntu/volume1/home/s124md303_06/.local/lib/python3.8/site-packages/tensorboard/backend/application.py", line 551, in _route_request
    return self.exact_routes[clean_path](environ, start_response)
  File "/media/ntu/volume1/home/s124md303_06/.local/lib/python3.8/site-packages/werkzeug/wrappers/request.py", line 190, in application
    resp = f(*args[:-2] + (request,))
  File "/media/ntu/volume1/home/s124md303_06/.local/lib/python3.8/site-packages/tensorboard/plugins/hparams/hparams_plugin.py", line 122, in get_experiment_route
    json_format.MessageToJson(
TypeError: MessageToJson() got an unexpected keyword argument 'including_default_value_fields'
E0309 14:35:51.866586 140527320807168 _internal.py:97] Error on request:
Traceback (most recent call last):
  File "/media/ntu/volume1/home/s124md303_06/.local/lib/python3.8/site-packages/werkzeug/serving.py", line 370, in run_wsgi
    execute(self.server.app)
  File "/media/ntu/volume1/home/s124md303_06/.local/lib/python3.8/site-packages/werkzeug/serving.py", line 331, in execute
    application_iter = app(environ, start_response)
  File "/media/ntu/volume1/home/s124md303_06/.local/lib/python3.8/site-packages/tensorboard/backend/application.py", line 528, in __call__
    return self._app(environ, start_response)
  File "/media/ntu/volume1/home/s124md303_06/.local/lib/python3.8/site-packages/tensorboard/backend/application.py", line 569, in wrapper
    return wsgi_app(environ, start_response)
  File "/media/ntu/volume1/home/s124md303_06/.local/lib/python3.8/site-packages/tensorboard/backend/security_validator.py", line 91, in __call__
    return self._application(environ, start_response_proxy)
  File "/media/ntu/volume1/home/s124md303_06/.local/lib/python3.8/site-packages/tensorboard/backend/path_prefix.py", line 68, in __call__
    return self._application(environ, start_response)
  File "/media/ntu/volume1/home/s124md303_06/.local/lib/python3.8/site-packages/tensorboard/backend/experiment_id.py", line 73, in __call__
    return self._application(environ, start_response)
  File "/media/ntu/volume1/home/s124md303_06/.local/lib/python3.8/site-packages/tensorboard/backend/empty_path_redirect.py", line 43, in __call__
    return self._application(environ, start_response)
  File "/media/ntu/volume1/home/s124md303_06/.local/lib/python3.8/site-packages/tensorboard/backend/client_feature_flags.py", line 55, in __call__
    return self._application(environ, start_response)
  File "/media/ntu/volume1/home/s124md303_06/.local/lib/python3.8/site-packages/tensorboard/backend/auth_context_middleware.py", line 38, in __call__
    return self._application(environ, start_response)
  File "/media/ntu/volume1/home/s124md303_06/.local/lib/python3.8/site-packages/tensorboard/backend/application.py", line 551, in _route_request
    return self.exact_routes[clean_path](environ, start_response)
  File "/media/ntu/volume1/home/s124md303_06/.local/lib/python3.8/site-packages/werkzeug/wrappers/request.py", line 190, in application
    resp = f(*args[:-2] + (request,))
  File "/media/ntu/volume1/home/s124md303_06/.local/lib/python3.8/site-packages/tensorboard/plugins/hparams/hparams_plugin.py", line 122, in get_experiment_route
    json_format.MessageToJson(
TypeError: MessageToJson() got an unexpected keyword argument 'including_default_value_fields'
E0309 14:36:21.869932 140527446648576 _internal.py:97] Error on request:
Traceback (most recent call last):
  File "/media/ntu/volume1/home/s124md303_06/.local/lib/python3.8/site-packages/werkzeug/serving.py", line 370, in run_wsgi
    execute(self.server.app)
  File "/media/ntu/volume1/home/s124md303_06/.local/lib/python3.8/site-packages/werkzeug/serving.py", line 331, in execute
    application_iter = app(environ, start_response)
  File "/media/ntu/volume1/home/s124md303_06/.local/lib/python3.8/site-packages/tensorboard/backend/application.py", line 528, in __call__
    return self._app(environ, start_response)
  File "/media/ntu/volume1/home/s124md303_06/.local/lib/python3.8/site-packages/tensorboard/backend/application.py", line 569, in wrapper
    return wsgi_app(environ, start_response)
  File "/media/ntu/volume1/home/s124md303_06/.local/lib/python3.8/site-packages/tensorboard/backend/security_validator.py", line 91, in __call__
    return self._application(environ, start_response_proxy)
  File "/media/ntu/volume1/home/s124md303_06/.local/lib/python3.8/site-packages/tensorboard/backend/path_prefix.py", line 68, in __call__
    return self._application(environ, start_response)
  File "/media/ntu/volume1/home/s124md303_06/.local/lib/python3.8/site-packages/tensorboard/backend/experiment_id.py", line 73, in __call__
    return self._application(environ, start_response)
  File "/media/ntu/volume1/home/s124md303_06/.local/lib/python3.8/site-packages/tensorboard/backend/empty_path_redirect.py", line 43, in __call__
    return self._application(environ, start_response)
  File "/media/ntu/volume1/home/s124md303_06/.local/lib/python3.8/site-packages/tensorboard/backend/client_feature_flags.py", line 55, in __call__
    return self._application(environ, start_response)
  File "/media/ntu/volume1/home/s124md303_06/.local/lib/python3.8/site-packages/tensorboard/backend/auth_context_middleware.py", line 38, in __call__
    return self._application(environ, start_response)
  File "/media/ntu/volume1/home/s124md303_06/.local/lib/python3.8/site-packages/tensorboard/backend/application.py", line 551, in _route_request
    return self.exact_routes[clean_path](environ, start_response)
  File "/media/ntu/volume1/home/s124md303_06/.local/lib/python3.8/site-packages/werkzeug/wrappers/request.py", line 190, in application
    resp = f(*args[:-2] + (request,))
  File "/media/ntu/volume1/home/s124md303_06/.local/lib/python3.8/site-packages/tensorboard/plugins/hparams/hparams_plugin.py", line 122, in get_experiment_route
    json_format.MessageToJson(
TypeError: MessageToJson() got an unexpected keyword argument 'including_default_value_fields'
E0309 14:36:51.884021 140527530542848 _internal.py:97] Error on request:
Traceback (most recent call last):
  File "/media/ntu/volume1/home/s124md303_06/.local/lib/python3.8/site-packages/werkzeug/serving.py", line 370, in run_wsgi
    execute(self.server.app)
  File "/media/ntu/volume1/home/s124md303_06/.local/lib/python3.8/site-packages/werkzeug/serving.py", line 331, in execute
    application_iter = app(environ, start_response)
  File "/media/ntu/volume1/home/s124md303_06/.local/lib/python3.8/site-packages/tensorboard/backend/application.py", line 528, in __call__
    return self._app(environ, start_response)
  File "/media/ntu/volume1/home/s124md303_06/.local/lib/python3.8/site-packages/tensorboard/backend/application.py", line 569, in wrapper
    return wsgi_app(environ, start_response)
  File "/media/ntu/volume1/home/s124md303_06/.local/lib/python3.8/site-packages/tensorboard/backend/security_validator.py", line 91, in __call__
    return self._application(environ, start_response_proxy)
  File "/media/ntu/volume1/home/s124md303_06/.local/lib/python3.8/site-packages/tensorboard/backend/path_prefix.py", line 68, in __call__
    return self._application(environ, start_response)
  File "/media/ntu/volume1/home/s124md303_06/.local/lib/python3.8/site-packages/tensorboard/backend/experiment_id.py", line 73, in __call__
    return self._application(environ, start_response)
  File "/media/ntu/volume1/home/s124md303_06/.local/lib/python3.8/site-packages/tensorboard/backend/empty_path_redirect.py", line 43, in __call__
    return self._application(environ, start_response)
  File "/media/ntu/volume1/home/s124md303_06/.local/lib/python3.8/site-packages/tensorboard/backend/client_feature_flags.py", line 55, in __call__
    return self._application(environ, start_response)
  File "/media/ntu/volume1/home/s124md303_06/.local/lib/python3.8/site-packages/tensorboard/backend/auth_context_middleware.py", line 38, in __call__
    return self._application(environ, start_response)
  File "/media/ntu/volume1/home/s124md303_06/.local/lib/python3.8/site-packages/tensorboard/backend/application.py", line 551, in _route_request
    return self.exact_routes[clean_path](environ, start_response)
  File "/media/ntu/volume1/home/s124md303_06/.local/lib/python3.8/site-packages/werkzeug/wrappers/request.py", line 190, in application
    resp = f(*args[:-2] + (request,))
  File "/media/ntu/volume1/home/s124md303_06/.local/lib/python3.8/site-packages/tensorboard/plugins/hparams/hparams_plugin.py", line 122, in get_experiment_route
    json_format.MessageToJson(
TypeError: MessageToJson() got an unexpected keyword argument 'including_default_value_fields'
E0309 14:37:21.897455 140527530542848 _internal.py:97] Error on request:
Traceback (most recent call last):
  File "/media/ntu/volume1/home/s124md303_06/.local/lib/python3.8/site-packages/werkzeug/serving.py", line 370, in run_wsgi
    execute(self.server.app)
  File "/media/ntu/volume1/home/s124md303_06/.local/lib/python3.8/site-packages/werkzeug/serving.py", line 331, in execute
    application_iter = app(environ, start_response)
  File "/media/ntu/volume1/home/s124md303_06/.local/lib/python3.8/site-packages/tensorboard/backend/application.py", line 528, in __call__
    return self._app(environ, start_response)
  File "/media/ntu/volume1/home/s124md303_06/.local/lib/python3.8/site-packages/tensorboard/backend/application.py", line 569, in wrapper
    return wsgi_app(environ, start_response)
  File "/media/ntu/volume1/home/s124md303_06/.local/lib/python3.8/site-packages/tensorboard/backend/security_validator.py", line 91, in __call__
    return self._application(environ, start_response_proxy)
  File "/media/ntu/volume1/home/s124md303_06/.local/lib/python3.8/site-packages/tensorboard/backend/path_prefix.py", line 68, in __call__
    return self._application(environ, start_response)
  File "/media/ntu/volume1/home/s124md303_06/.local/lib/python3.8/site-packages/tensorboard/backend/experiment_id.py", line 73, in __call__
    return self._application(environ, start_response)
  File "/media/ntu/volume1/home/s124md303_06/.local/lib/python3.8/site-packages/tensorboard/backend/empty_path_redirect.py", line 43, in __call__
    return self._application(environ, start_response)
  File "/media/ntu/volume1/home/s124md303_06/.local/lib/python3.8/site-packages/tensorboard/backend/client_feature_flags.py", line 55, in __call__
    return self._application(environ, start_response)
  File "/media/ntu/volume1/home/s124md303_06/.local/lib/python3.8/site-packages/tensorboard/backend/auth_context_middleware.py", line 38, in __call__
    return self._application(environ, start_response)
  File "/media/ntu/volume1/home/s124md303_06/.local/lib/python3.8/site-packages/tensorboard/backend/application.py", line 551, in _route_request
    return self.exact_routes[clean_path](environ, start_response)
  File "/media/ntu/volume1/home/s124md303_06/.local/lib/python3.8/site-packages/werkzeug/wrappers/request.py", line 190, in application
    resp = f(*args[:-2] + (request,))
  File "/media/ntu/volume1/home/s124md303_06/.local/lib/python3.8/site-packages/tensorboard/plugins/hparams/hparams_plugin.py", line 122, in get_experiment_route
    json_format.MessageToJson(
TypeError: MessageToJson() got an unexpected keyword argument 'including_default_value_fields'
E0309 14:37:51.917407 140527404701440 _internal.py:97] Error on request:
Traceback (most recent call last):
  File "/media/ntu/volume1/home/s124md303_06/.local/lib/python3.8/site-packages/werkzeug/serving.py", line 370, in run_wsgi
    execute(self.server.app)
  File "/media/ntu/volume1/home/s124md303_06/.local/lib/python3.8/site-packages/werkzeug/serving.py", line 331, in execute
    application_iter = app(environ, start_response)
  File "/media/ntu/volume1/home/s124md303_06/.local/lib/python3.8/site-packages/tensorboard/backend/application.py", line 528, in __call__
    return self._app(environ, start_response)
  File "/media/ntu/volume1/home/s124md303_06/.local/lib/python3.8/site-packages/tensorboard/backend/application.py", line 569, in wrapper
    return wsgi_app(environ, start_response)
  File "/media/ntu/volume1/home/s124md303_06/.local/lib/python3.8/site-packages/tensorboard/backend/security_validator.py", line 91, in __call__
    return self._application(environ, start_response_proxy)
  File "/media/ntu/volume1/home/s124md303_06/.local/lib/python3.8/site-packages/tensorboard/backend/path_prefix.py", line 68, in __call__
    return self._application(environ, start_response)
  File "/media/ntu/volume1/home/s124md303_06/.local/lib/python3.8/site-packages/tensorboard/backend/experiment_id.py", line 73, in __call__
    return self._application(environ, start_response)
  File "/media/ntu/volume1/home/s124md303_06/.local/lib/python3.8/site-packages/tensorboard/backend/empty_path_redirect.py", line 43, in __call__
    return self._application(environ, start_response)
  File "/media/ntu/volume1/home/s124md303_06/.local/lib/python3.8/site-packages/tensorboard/backend/client_feature_flags.py", line 55, in __call__
    return self._application(environ, start_response)
  File "/media/ntu/volume1/home/s124md303_06/.local/lib/python3.8/site-packages/tensorboard/backend/auth_context_middleware.py", line 38, in __call__
    return self._application(environ, start_response)
  File "/media/ntu/volume1/home/s124md303_06/.local/lib/python3.8/site-packages/tensorboard/backend/application.py", line 551, in _route_request
    return self.exact_routes[clean_path](environ, start_response)
  File "/media/ntu/volume1/home/s124md303_06/.local/lib/python3.8/site-packages/werkzeug/wrappers/request.py", line 190, in application
    resp = f(*args[:-2] + (request,))
  File "/media/ntu/volume1/home/s124md303_06/.local/lib/python3.8/site-packages/tensorboard/plugins/hparams/hparams_plugin.py", line 122, in get_experiment_route
    json_format.MessageToJson(
TypeError: MessageToJson() got an unexpected keyword argument 'including_default_value_fields'
E0309 14:38:21.932838 140527404701440 _internal.py:97] Error on request:
Traceback (most recent call last):
  File "/media/ntu/volume1/home/s124md303_06/.local/lib/python3.8/site-packages/werkzeug/serving.py", line 370, in run_wsgi
    execute(self.server.app)
  File "/media/ntu/volume1/home/s124md303_06/.local/lib/python3.8/site-packages/werkzeug/serving.py", line 331, in execute
    application_iter = app(environ, start_response)
  File "/media/ntu/volume1/home/s124md303_06/.local/lib/python3.8/site-packages/tensorboard/backend/application.py", line 528, in __call__
    return self._app(environ, start_response)
  File "/media/ntu/volume1/home/s124md303_06/.local/lib/python3.8/site-packages/tensorboard/backend/application.py", line 569, in wrapper
    return wsgi_app(environ, start_response)
  File "/media/ntu/volume1/home/s124md303_06/.local/lib/python3.8/site-packages/tensorboard/backend/security_validator.py", line 91, in __call__
    return self._application(environ, start_response_proxy)
  File "/media/ntu/volume1/home/s124md303_06/.local/lib/python3.8/site-packages/tensorboard/backend/path_prefix.py", line 68, in __call__
    return self._application(environ, start_response)
  File "/media/ntu/volume1/home/s124md303_06/.local/lib/python3.8/site-packages/tensorboard/backend/experiment_id.py", line 73, in __call__
    return self._application(environ, start_response)
  File "/media/ntu/volume1/home/s124md303_06/.local/lib/python3.8/site-packages/tensorboard/backend/empty_path_redirect.py", line 43, in __call__
    return self._application(environ, start_response)
  File "/media/ntu/volume1/home/s124md303_06/.local/lib/python3.8/site-packages/tensorboard/backend/client_feature_flags.py", line 55, in __call__
    return self._application(environ, start_response)
  File "/media/ntu/volume1/home/s124md303_06/.local/lib/python3.8/site-packages/tensorboard/backend/auth_context_middleware.py", line 38, in __call__
    return self._application(environ, start_response)
  File "/media/ntu/volume1/home/s124md303_06/.local/lib/python3.8/site-packages/tensorboard/backend/application.py", line 551, in _route_request
    return self.exact_routes[clean_path](environ, start_response)
  File "/media/ntu/volume1/home/s124md303_06/.local/lib/python3.8/site-packages/werkzeug/wrappers/request.py", line 190, in application
    resp = f(*args[:-2] + (request,))
  File "/media/ntu/volume1/home/s124md303_06/.local/lib/python3.8/site-packages/tensorboard/plugins/hparams/hparams_plugin.py", line 122, in get_experiment_route
    json_format.MessageToJson(
TypeError: MessageToJson() got an unexpected keyword argument 'including_default_value_fields'
E0309 14:38:51.948031 140527446648576 _internal.py:97] Error on request:
Traceback (most recent call last):
  File "/media/ntu/volume1/home/s124md303_06/.local/lib/python3.8/site-packages/werkzeug/serving.py", line 370, in run_wsgi
    execute(self.server.app)
  File "/media/ntu/volume1/home/s124md303_06/.local/lib/python3.8/site-packages/werkzeug/serving.py", line 331, in execute
    application_iter = app(environ, start_response)
  File "/media/ntu/volume1/home/s124md303_06/.local/lib/python3.8/site-packages/tensorboard/backend/application.py", line 528, in __call__
    return self._app(environ, start_response)
  File "/media/ntu/volume1/home/s124md303_06/.local/lib/python3.8/site-packages/tensorboard/backend/application.py", line 569, in wrapper
    return wsgi_app(environ, start_response)
  File "/media/ntu/volume1/home/s124md303_06/.local/lib/python3.8/site-packages/tensorboard/backend/security_validator.py", line 91, in __call__
    return self._application(environ, start_response_proxy)
  File "/media/ntu/volume1/home/s124md303_06/.local/lib/python3.8/site-packages/tensorboard/backend/path_prefix.py", line 68, in __call__
    return self._application(environ, start_response)
  File "/media/ntu/volume1/home/s124md303_06/.local/lib/python3.8/site-packages/tensorboard/backend/experiment_id.py", line 73, in __call__
    return self._application(environ, start_response)
  File "/media/ntu/volume1/home/s124md303_06/.local/lib/python3.8/site-packages/tensorboard/backend/empty_path_redirect.py", line 43, in __call__
    return self._application(environ, start_response)
  File "/media/ntu/volume1/home/s124md303_06/.local/lib/python3.8/site-packages/tensorboard/backend/client_feature_flags.py", line 55, in __call__
    return self._application(environ, start_response)
  File "/media/ntu/volume1/home/s124md303_06/.local/lib/python3.8/site-packages/tensorboard/backend/auth_context_middleware.py", line 38, in __call__
    return self._application(environ, start_response)
  File "/media/ntu/volume1/home/s124md303_06/.local/lib/python3.8/site-packages/tensorboard/backend/application.py", line 551, in _route_request
    return self.exact_routes[clean_path](environ, start_response)
  File "/media/ntu/volume1/home/s124md303_06/.local/lib/python3.8/site-packages/werkzeug/wrappers/request.py", line 190, in application
    resp = f(*args[:-2] + (request,))
  File "/media/ntu/volume1/home/s124md303_06/.local/lib/python3.8/site-packages/tensorboard/plugins/hparams/hparams_plugin.py", line 122, in get_experiment_route
    json_format.MessageToJson(
TypeError: MessageToJson() got an unexpected keyword argument 'including_default_value_fields'
E0309 14:39:21.959046 140527530542848 _internal.py:97] Error on request:
Traceback (most recent call last):
  File "/media/ntu/volume1/home/s124md303_06/.local/lib/python3.8/site-packages/werkzeug/serving.py", line 370, in run_wsgi
    execute(self.server.app)
  File "/media/ntu/volume1/home/s124md303_06/.local/lib/python3.8/site-packages/werkzeug/serving.py", line 331, in execute
    application_iter = app(environ, start_response)
  File "/media/ntu/volume1/home/s124md303_06/.local/lib/python3.8/site-packages/tensorboard/backend/application.py", line 528, in __call__
    return self._app(environ, start_response)
  File "/media/ntu/volume1/home/s124md303_06/.local/lib/python3.8/site-packages/tensorboard/backend/application.py", line 569, in wrapper
    return wsgi_app(environ, start_response)
  File "/media/ntu/volume1/home/s124md303_06/.local/lib/python3.8/site-packages/tensorboard/backend/security_validator.py", line 91, in __call__
    return self._application(environ, start_response_proxy)
  File "/media/ntu/volume1/home/s124md303_06/.local/lib/python3.8/site-packages/tensorboard/backend/path_prefix.py", line 68, in __call__
    return self._application(environ, start_response)
  File "/media/ntu/volume1/home/s124md303_06/.local/lib/python3.8/site-packages/tensorboard/backend/experiment_id.py", line 73, in __call__
    return self._application(environ, start_response)
  File "/media/ntu/volume1/home/s124md303_06/.local/lib/python3.8/site-packages/tensorboard/backend/empty_path_redirect.py", line 43, in __call__
    return self._application(environ, start_response)
  File "/media/ntu/volume1/home/s124md303_06/.local/lib/python3.8/site-packages/tensorboard/backend/client_feature_flags.py", line 55, in __call__
    return self._application(environ, start_response)
  File "/media/ntu/volume1/home/s124md303_06/.local/lib/python3.8/site-packages/tensorboard/backend/auth_context_middleware.py", line 38, in __call__
    return self._application(environ, start_response)
  File "/media/ntu/volume1/home/s124md303_06/.local/lib/python3.8/site-packages/tensorboard/backend/application.py", line 551, in _route_request
    return self.exact_routes[clean_path](environ, start_response)
  File "/media/ntu/volume1/home/s124md303_06/.local/lib/python3.8/site-packages/werkzeug/wrappers/request.py", line 190, in application
    resp = f(*args[:-2] + (request,))
  File "/media/ntu/volume1/home/s124md303_06/.local/lib/python3.8/site-packages/tensorboard/plugins/hparams/hparams_plugin.py", line 122, in get_experiment_route
    json_format.MessageToJson(
TypeError: MessageToJson() got an unexpected keyword argument 'including_default_value_fields'
E0309 14:39:51.980955 140527488595712 _internal.py:97] Error on request:
Traceback (most recent call last):
  File "/media/ntu/volume1/home/s124md303_06/.local/lib/python3.8/site-packages/werkzeug/serving.py", line 370, in run_wsgi
    execute(self.server.app)
  File "/media/ntu/volume1/home/s124md303_06/.local/lib/python3.8/site-packages/werkzeug/serving.py", line 331, in execute
    application_iter = app(environ, start_response)
  File "/media/ntu/volume1/home/s124md303_06/.local/lib/python3.8/site-packages/tensorboard/backend/application.py", line 528, in __call__
    return self._app(environ, start_response)
  File "/media/ntu/volume1/home/s124md303_06/.local/lib/python3.8/site-packages/tensorboard/backend/application.py", line 569, in wrapper
    return wsgi_app(environ, start_response)
  File "/media/ntu/volume1/home/s124md303_06/.local/lib/python3.8/site-packages/tensorboard/backend/security_validator.py", line 91, in __call__
    return self._application(environ, start_response_proxy)
  File "/media/ntu/volume1/home/s124md303_06/.local/lib/python3.8/site-packages/tensorboard/backend/path_prefix.py", line 68, in __call__
    return self._application(environ, start_response)
  File "/media/ntu/volume1/home/s124md303_06/.local/lib/python3.8/site-packages/tensorboard/backend/experiment_id.py", line 73, in __call__
    return self._application(environ, start_response)
  File "/media/ntu/volume1/home/s124md303_06/.local/lib/python3.8/site-packages/tensorboard/backend/empty_path_redirect.py", line 43, in __call__
    return self._application(environ, start_response)
  File "/media/ntu/volume1/home/s124md303_06/.local/lib/python3.8/site-packages/tensorboard/backend/client_feature_flags.py", line 55, in __call__
    return self._application(environ, start_response)
  File "/media/ntu/volume1/home/s124md303_06/.local/lib/python3.8/site-packages/tensorboard/backend/auth_context_middleware.py", line 38, in __call__
    return self._application(environ, start_response)
  File "/media/ntu/volume1/home/s124md303_06/.local/lib/python3.8/site-packages/tensorboard/backend/application.py", line 551, in _route_request
    return self.exact_routes[clean_path](environ, start_response)
  File "/media/ntu/volume1/home/s124md303_06/.local/lib/python3.8/site-packages/werkzeug/wrappers/request.py", line 190, in application
    resp = f(*args[:-2] + (request,))
  File "/media/ntu/volume1/home/s124md303_06/.local/lib/python3.8/site-packages/tensorboard/plugins/hparams/hparams_plugin.py", line 122, in get_experiment_route
    json_format.MessageToJson(
TypeError: MessageToJson() got an unexpected keyword argument 'including_default_value_fields'
E0309 14:40:21.982997 140527580358400 _internal.py:97] Error on request:
Traceback (most recent call last):
  File "/media/ntu/volume1/home/s124md303_06/.local/lib/python3.8/site-packages/werkzeug/serving.py", line 370, in run_wsgi
    execute(self.server.app)
  File "/media/ntu/volume1/home/s124md303_06/.local/lib/python3.8/site-packages/werkzeug/serving.py", line 331, in execute
    application_iter = app(environ, start_response)
  File "/media/ntu/volume1/home/s124md303_06/.local/lib/python3.8/site-packages/tensorboard/backend/application.py", line 528, in __call__
    return self._app(environ, start_response)
  File "/media/ntu/volume1/home/s124md303_06/.local/lib/python3.8/site-packages/tensorboard/backend/application.py", line 569, in wrapper
    return wsgi_app(environ, start_response)
  File "/media/ntu/volume1/home/s124md303_06/.local/lib/python3.8/site-packages/tensorboard/backend/security_validator.py", line 91, in __call__
    return self._application(environ, start_response_proxy)
  File "/media/ntu/volume1/home/s124md303_06/.local/lib/python3.8/site-packages/tensorboard/backend/path_prefix.py", line 68, in __call__
    return self._application(environ, start_response)
  File "/media/ntu/volume1/home/s124md303_06/.local/lib/python3.8/site-packages/tensorboard/backend/experiment_id.py", line 73, in __call__
    return self._application(environ, start_response)
  File "/media/ntu/volume1/home/s124md303_06/.local/lib/python3.8/site-packages/tensorboard/backend/empty_path_redirect.py", line 43, in __call__
    return self._application(environ, start_response)
  File "/media/ntu/volume1/home/s124md303_06/.local/lib/python3.8/site-packages/tensorboard/backend/client_feature_flags.py", line 55, in __call__
    return self._application(environ, start_response)
  File "/media/ntu/volume1/home/s124md303_06/.local/lib/python3.8/site-packages/tensorboard/backend/auth_context_middleware.py", line 38, in __call__
    return self._application(environ, start_response)
  File "/media/ntu/volume1/home/s124md303_06/.local/lib/python3.8/site-packages/tensorboard/backend/application.py", line 551, in _route_request
    return self.exact_routes[clean_path](environ, start_response)
  File "/media/ntu/volume1/home/s124md303_06/.local/lib/python3.8/site-packages/werkzeug/wrappers/request.py", line 190, in application
    resp = f(*args[:-2] + (request,))
  File "/media/ntu/volume1/home/s124md303_06/.local/lib/python3.8/site-packages/tensorboard/plugins/hparams/hparams_plugin.py", line 122, in get_experiment_route
    json_format.MessageToJson(
TypeError: MessageToJson() got an unexpected keyword argument 'including_default_value_fields'
E0309 14:40:51.997683 140527530542848 _internal.py:97] Error on request:
Traceback (most recent call last):
  File "/media/ntu/volume1/home/s124md303_06/.local/lib/python3.8/site-packages/werkzeug/serving.py", line 370, in run_wsgi
    execute(self.server.app)
  File "/media/ntu/volume1/home/s124md303_06/.local/lib/python3.8/site-packages/werkzeug/serving.py", line 331, in execute
    application_iter = app(environ, start_response)
  File "/media/ntu/volume1/home/s124md303_06/.local/lib/python3.8/site-packages/tensorboard/backend/application.py", line 528, in __call__
    return self._app(environ, start_response)
  File "/media/ntu/volume1/home/s124md303_06/.local/lib/python3.8/site-packages/tensorboard/backend/application.py", line 569, in wrapper
    return wsgi_app(environ, start_response)
  File "/media/ntu/volume1/home/s124md303_06/.local/lib/python3.8/site-packages/tensorboard/backend/security_validator.py", line 91, in __call__
    return self._application(environ, start_response_proxy)
  File "/media/ntu/volume1/home/s124md303_06/.local/lib/python3.8/site-packages/tensorboard/backend/path_prefix.py", line 68, in __call__
    return self._application(environ, start_response)
  File "/media/ntu/volume1/home/s124md303_06/.local/lib/python3.8/site-packages/tensorboard/backend/experiment_id.py", line 73, in __call__
    return self._application(environ, start_response)
  File "/media/ntu/volume1/home/s124md303_06/.local/lib/python3.8/site-packages/tensorboard/backend/empty_path_redirect.py", line 43, in __call__
    return self._application(environ, start_response)
  File "/media/ntu/volume1/home/s124md303_06/.local/lib/python3.8/site-packages/tensorboard/backend/client_feature_flags.py", line 55, in __call__
    return self._application(environ, start_response)
  File "/media/ntu/volume1/home/s124md303_06/.local/lib/python3.8/site-packages/tensorboard/backend/auth_context_middleware.py", line 38, in __call__
    return self._application(environ, start_response)
  File "/media/ntu/volume1/home/s124md303_06/.local/lib/python3.8/site-packages/tensorboard/backend/application.py", line 551, in _route_request
    return self.exact_routes[clean_path](environ, start_response)
  File "/media/ntu/volume1/home/s124md303_06/.local/lib/python3.8/site-packages/werkzeug/wrappers/request.py", line 190, in application
    resp = f(*args[:-2] + (request,))
  File "/media/ntu/volume1/home/s124md303_06/.local/lib/python3.8/site-packages/tensorboard/plugins/hparams/hparams_plugin.py", line 122, in get_experiment_route
    json_format.MessageToJson(
TypeError: MessageToJson() got an unexpected keyword argument 'including_default_value_fields'
E0309 14:41:17.093881 140527580358400 _internal.py:97] Error on request:
Traceback (most recent call last):
  File "/media/ntu/volume1/home/s124md303_06/.local/lib/python3.8/site-packages/werkzeug/serving.py", line 370, in run_wsgi
    execute(self.server.app)
  File "/media/ntu/volume1/home/s124md303_06/.local/lib/python3.8/site-packages/werkzeug/serving.py", line 331, in execute
    application_iter = app(environ, start_response)
  File "/media/ntu/volume1/home/s124md303_06/.local/lib/python3.8/site-packages/tensorboard/backend/application.py", line 528, in __call__
    return self._app(environ, start_response)
  File "/media/ntu/volume1/home/s124md303_06/.local/lib/python3.8/site-packages/tensorboard/backend/application.py", line 569, in wrapper
    return wsgi_app(environ, start_response)
  File "/media/ntu/volume1/home/s124md303_06/.local/lib/python3.8/site-packages/tensorboard/backend/security_validator.py", line 91, in __call__
    return self._application(environ, start_response_proxy)
  File "/media/ntu/volume1/home/s124md303_06/.local/lib/python3.8/site-packages/tensorboard/backend/path_prefix.py", line 68, in __call__
    return self._application(environ, start_response)
  File "/media/ntu/volume1/home/s124md303_06/.local/lib/python3.8/site-packages/tensorboard/backend/experiment_id.py", line 73, in __call__
    return self._application(environ, start_response)
  File "/media/ntu/volume1/home/s124md303_06/.local/lib/python3.8/site-packages/tensorboard/backend/empty_path_redirect.py", line 43, in __call__
    return self._application(environ, start_response)
  File "/media/ntu/volume1/home/s124md303_06/.local/lib/python3.8/site-packages/tensorboard/backend/client_feature_flags.py", line 55, in __call__
    return self._application(environ, start_response)
  File "/media/ntu/volume1/home/s124md303_06/.local/lib/python3.8/site-packages/tensorboard/backend/auth_context_middleware.py", line 38, in __call__
    return self._application(environ, start_response)
  File "/media/ntu/volume1/home/s124md303_06/.local/lib/python3.8/site-packages/tensorboard/backend/application.py", line 551, in _route_request
    return self.exact_routes[clean_path](environ, start_response)
  File "/media/ntu/volume1/home/s124md303_06/.local/lib/python3.8/site-packages/werkzeug/wrappers/request.py", line 190, in application
    resp = f(*args[:-2] + (request,))
  File "/media/ntu/volume1/home/s124md303_06/.local/lib/python3.8/site-packages/tensorboard/plugins/hparams/hparams_plugin.py", line 122, in get_experiment_route
    json_format.MessageToJson(
TypeError: MessageToJson() got an unexpected keyword argument 'including_default_value_fields'
E0309 14:41:17.270643 140527404701440 _internal.py:97] Error on request:
Traceback (most recent call last):
  File "/media/ntu/volume1/home/s124md303_06/.local/lib/python3.8/site-packages/werkzeug/serving.py", line 370, in run_wsgi
    execute(self.server.app)
  File "/media/ntu/volume1/home/s124md303_06/.local/lib/python3.8/site-packages/werkzeug/serving.py", line 331, in execute
    application_iter = app(environ, start_response)
  File "/media/ntu/volume1/home/s124md303_06/.local/lib/python3.8/site-packages/tensorboard/backend/application.py", line 528, in __call__
    return self._app(environ, start_response)
  File "/media/ntu/volume1/home/s124md303_06/.local/lib/python3.8/site-packages/tensorboard/backend/application.py", line 569, in wrapper
    return wsgi_app(environ, start_response)
  File "/media/ntu/volume1/home/s124md303_06/.local/lib/python3.8/site-packages/tensorboard/backend/security_validator.py", line 91, in __call__
    return self._application(environ, start_response_proxy)
  File "/media/ntu/volume1/home/s124md303_06/.local/lib/python3.8/site-packages/tensorboard/backend/path_prefix.py", line 68, in __call__
    return self._application(environ, start_response)
  File "/media/ntu/volume1/home/s124md303_06/.local/lib/python3.8/site-packages/tensorboard/backend/experiment_id.py", line 73, in __call__
    return self._application(environ, start_response)
  File "/media/ntu/volume1/home/s124md303_06/.local/lib/python3.8/site-packages/tensorboard/backend/empty_path_redirect.py", line 43, in __call__
    return self._application(environ, start_response)
  File "/media/ntu/volume1/home/s124md303_06/.local/lib/python3.8/site-packages/tensorboard/backend/client_feature_flags.py", line 55, in __call__
    return self._application(environ, start_response)
  File "/media/ntu/volume1/home/s124md303_06/.local/lib/python3.8/site-packages/tensorboard/backend/auth_context_middleware.py", line 38, in __call__
    return self._application(environ, start_response)
  File "/media/ntu/volume1/home/s124md303_06/.local/lib/python3.8/site-packages/tensorboard/backend/application.py", line 551, in _route_request
    return self.exact_routes[clean_path](environ, start_response)
  File "/media/ntu/volume1/home/s124md303_06/.local/lib/python3.8/site-packages/werkzeug/wrappers/request.py", line 190, in application
    resp = f(*args[:-2] + (request,))
  File "/media/ntu/volume1/home/s124md303_06/.local/lib/python3.8/site-packages/tensorboard/plugins/hparams/hparams_plugin.py", line 122, in get_experiment_route
    json_format.MessageToJson(
TypeError: MessageToJson() got an unexpected keyword argument 'including_default_value_fields'
E0309 14:41:18.779042 140527530542848 _internal.py:97] Error on request:
Traceback (most recent call last):
  File "/media/ntu/volume1/home/s124md303_06/.local/lib/python3.8/site-packages/werkzeug/serving.py", line 370, in run_wsgi
    execute(self.server.app)
  File "/media/ntu/volume1/home/s124md303_06/.local/lib/python3.8/site-packages/werkzeug/serving.py", line 331, in execute
    application_iter = app(environ, start_response)
  File "/media/ntu/volume1/home/s124md303_06/.local/lib/python3.8/site-packages/tensorboard/backend/application.py", line 528, in __call__
    return self._app(environ, start_response)
  File "/media/ntu/volume1/home/s124md303_06/.local/lib/python3.8/site-packages/tensorboard/backend/application.py", line 569, in wrapper
    return wsgi_app(environ, start_response)
  File "/media/ntu/volume1/home/s124md303_06/.local/lib/python3.8/site-packages/tensorboard/backend/security_validator.py", line 91, in __call__
    return self._application(environ, start_response_proxy)
  File "/media/ntu/volume1/home/s124md303_06/.local/lib/python3.8/site-packages/tensorboard/backend/path_prefix.py", line 68, in __call__
    return self._application(environ, start_response)
  File "/media/ntu/volume1/home/s124md303_06/.local/lib/python3.8/site-packages/tensorboard/backend/experiment_id.py", line 73, in __call__
    return self._application(environ, start_response)
  File "/media/ntu/volume1/home/s124md303_06/.local/lib/python3.8/site-packages/tensorboard/backend/empty_path_redirect.py", line 43, in __call__
    return self._application(environ, start_response)
  File "/media/ntu/volume1/home/s124md303_06/.local/lib/python3.8/site-packages/tensorboard/backend/client_feature_flags.py", line 55, in __call__
    return self._application(environ, start_response)
  File "/media/ntu/volume1/home/s124md303_06/.local/lib/python3.8/site-packages/tensorboard/backend/auth_context_middleware.py", line 38, in __call__
    return self._application(environ, start_response)
  File "/media/ntu/volume1/home/s124md303_06/.local/lib/python3.8/site-packages/tensorboard/backend/application.py", line 551, in _route_request
    return self.exact_routes[clean_path](environ, start_response)
  File "/media/ntu/volume1/home/s124md303_06/.local/lib/python3.8/site-packages/werkzeug/wrappers/request.py", line 190, in application
    resp = f(*args[:-2] + (request,))
  File "/media/ntu/volume1/home/s124md303_06/.local/lib/python3.8/site-packages/tensorboard/plugins/hparams/hparams_plugin.py", line 122, in get_experiment_route
    json_format.MessageToJson(
TypeError: MessageToJson() got an unexpected keyword argument 'including_default_value_fields'
E0309 14:41:18.895531 140527488595712 _internal.py:97] Error on request:
Traceback (most recent call last):
  File "/media/ntu/volume1/home/s124md303_06/.local/lib/python3.8/site-packages/werkzeug/serving.py", line 370, in run_wsgi
    execute(self.server.app)
  File "/media/ntu/volume1/home/s124md303_06/.local/lib/python3.8/site-packages/werkzeug/serving.py", line 331, in execute
    application_iter = app(environ, start_response)
  File "/media/ntu/volume1/home/s124md303_06/.local/lib/python3.8/site-packages/tensorboard/backend/application.py", line 528, in __call__
    return self._app(environ, start_response)
  File "/media/ntu/volume1/home/s124md303_06/.local/lib/python3.8/site-packages/tensorboard/backend/application.py", line 569, in wrapper
    return wsgi_app(environ, start_response)
  File "/media/ntu/volume1/home/s124md303_06/.local/lib/python3.8/site-packages/tensorboard/backend/security_validator.py", line 91, in __call__
    return self._application(environ, start_response_proxy)
  File "/media/ntu/volume1/home/s124md303_06/.local/lib/python3.8/site-packages/tensorboard/backend/path_prefix.py", line 68, in __call__
    return self._application(environ, start_response)
  File "/media/ntu/volume1/home/s124md303_06/.local/lib/python3.8/site-packages/tensorboard/backend/experiment_id.py", line 73, in __call__
    return self._application(environ, start_response)
  File "/media/ntu/volume1/home/s124md303_06/.local/lib/python3.8/site-packages/tensorboard/backend/empty_path_redirect.py", line 43, in __call__
    return self._application(environ, start_response)
  File "/media/ntu/volume1/home/s124md303_06/.local/lib/python3.8/site-packages/tensorboard/backend/client_feature_flags.py", line 55, in __call__
    return self._application(environ, start_response)
  File "/media/ntu/volume1/home/s124md303_06/.local/lib/python3.8/site-packages/tensorboard/backend/auth_context_middleware.py", line 38, in __call__
    return self._application(environ, start_response)
  File "/media/ntu/volume1/home/s124md303_06/.local/lib/python3.8/site-packages/tensorboard/backend/application.py", line 551, in _route_request
    return self.exact_routes[clean_path](environ, start_response)
  File "/media/ntu/volume1/home/s124md303_06/.local/lib/python3.8/site-packages/werkzeug/wrappers/request.py", line 190, in application
    resp = f(*args[:-2] + (request,))
  File "/media/ntu/volume1/home/s124md303_06/.local/lib/python3.8/site-packages/tensorboard/plugins/hparams/hparams_plugin.py", line 122, in get_experiment_route
    json_format.MessageToJson(
TypeError: MessageToJson() got an unexpected keyword argument 'including_default_value_fields'
E0309 18:37:48.284565 140527446648576 _internal.py:97] Error on request:
Traceback (most recent call last):
  File "/media/ntu/volume1/home/s124md303_06/.local/lib/python3.8/site-packages/werkzeug/serving.py", line 370, in run_wsgi
    execute(self.server.app)
  File "/media/ntu/volume1/home/s124md303_06/.local/lib/python3.8/site-packages/werkzeug/serving.py", line 331, in execute
    application_iter = app(environ, start_response)
  File "/media/ntu/volume1/home/s124md303_06/.local/lib/python3.8/site-packages/tensorboard/backend/application.py", line 528, in __call__
    return self._app(environ, start_response)
  File "/media/ntu/volume1/home/s124md303_06/.local/lib/python3.8/site-packages/tensorboard/backend/application.py", line 569, in wrapper
    return wsgi_app(environ, start_response)
  File "/media/ntu/volume1/home/s124md303_06/.local/lib/python3.8/site-packages/tensorboard/backend/security_validator.py", line 91, in __call__
    return self._application(environ, start_response_proxy)
  File "/media/ntu/volume1/home/s124md303_06/.local/lib/python3.8/site-packages/tensorboard/backend/path_prefix.py", line 68, in __call__
    return self._application(environ, start_response)
  File "/media/ntu/volume1/home/s124md303_06/.local/lib/python3.8/site-packages/tensorboard/backend/experiment_id.py", line 73, in __call__
    return self._application(environ, start_response)
  File "/media/ntu/volume1/home/s124md303_06/.local/lib/python3.8/site-packages/tensorboard/backend/empty_path_redirect.py", line 43, in __call__
    return self._application(environ, start_response)
  File "/media/ntu/volume1/home/s124md303_06/.local/lib/python3.8/site-packages/tensorboard/backend/client_feature_flags.py", line 55, in __call__
    return self._application(environ, start_response)
  File "/media/ntu/volume1/home/s124md303_06/.local/lib/python3.8/site-packages/tensorboard/backend/auth_context_middleware.py", line 38, in __call__
    return self._application(environ, start_response)
  File "/media/ntu/volume1/home/s124md303_06/.local/lib/python3.8/site-packages/tensorboard/backend/application.py", line 551, in _route_request
    return self.exact_routes[clean_path](environ, start_response)
  File "/media/ntu/volume1/home/s124md303_06/.local/lib/python3.8/site-packages/werkzeug/wrappers/request.py", line 190, in application
    resp = f(*args[:-2] + (request,))
  File "/media/ntu/volume1/home/s124md303_06/.local/lib/python3.8/site-packages/tensorboard/plugins/hparams/hparams_plugin.py", line 122, in get_experiment_route
    json_format.MessageToJson(
TypeError: MessageToJson() got an unexpected keyword argument 'including_default_value_fields'
E0309 18:37:48.698356 140527320807168 _internal.py:97] Error on request:
Traceback (most recent call last):
  File "/media/ntu/volume1/home/s124md303_06/.local/lib/python3.8/site-packages/werkzeug/serving.py", line 370, in run_wsgi
    execute(self.server.app)
  File "/media/ntu/volume1/home/s124md303_06/.local/lib/python3.8/site-packages/werkzeug/serving.py", line 331, in execute
    application_iter = app(environ, start_response)
  File "/media/ntu/volume1/home/s124md303_06/.local/lib/python3.8/site-packages/tensorboard/backend/application.py", line 528, in __call__
    return self._app(environ, start_response)
  File "/media/ntu/volume1/home/s124md303_06/.local/lib/python3.8/site-packages/tensorboard/backend/application.py", line 569, in wrapper
    return wsgi_app(environ, start_response)
  File "/media/ntu/volume1/home/s124md303_06/.local/lib/python3.8/site-packages/tensorboard/backend/security_validator.py", line 91, in __call__
    return self._application(environ, start_response_proxy)
  File "/media/ntu/volume1/home/s124md303_06/.local/lib/python3.8/site-packages/tensorboard/backend/path_prefix.py", line 68, in __call__
    return self._application(environ, start_response)
  File "/media/ntu/volume1/home/s124md303_06/.local/lib/python3.8/site-packages/tensorboard/backend/experiment_id.py", line 73, in __call__
    return self._application(environ, start_response)
  File "/media/ntu/volume1/home/s124md303_06/.local/lib/python3.8/site-packages/tensorboard/backend/empty_path_redirect.py", line 43, in __call__
    return self._application(environ, start_response)
  File "/media/ntu/volume1/home/s124md303_06/.local/lib/python3.8/site-packages/tensorboard/backend/client_feature_flags.py", line 55, in __call__
    return self._application(environ, start_response)
  File "/media/ntu/volume1/home/s124md303_06/.local/lib/python3.8/site-packages/tensorboard/backend/auth_context_middleware.py", line 38, in __call__
    return self._application(environ, start_response)
  File "/media/ntu/volume1/home/s124md303_06/.local/lib/python3.8/site-packages/tensorboard/backend/application.py", line 551, in _route_request
    return self.exact_routes[clean_path](environ, start_response)
  File "/media/ntu/volume1/home/s124md303_06/.local/lib/python3.8/site-packages/werkzeug/wrappers/request.py", line 190, in application
    resp = f(*args[:-2] + (request,))
  File "/media/ntu/volume1/home/s124md303_06/.local/lib/python3.8/site-packages/tensorboard/plugins/hparams/hparams_plugin.py", line 122, in get_experiment_route
    json_format.MessageToJson(
TypeError: MessageToJson() got an unexpected keyword argument 'including_default_value_fields'
E0309 18:37:56.340836 140527530542848 _internal.py:97] Error on request:
Traceback (most recent call last):
  File "/media/ntu/volume1/home/s124md303_06/.local/lib/python3.8/site-packages/werkzeug/serving.py", line 370, in run_wsgi
    execute(self.server.app)
  File "/media/ntu/volume1/home/s124md303_06/.local/lib/python3.8/site-packages/werkzeug/serving.py", line 331, in execute
    application_iter = app(environ, start_response)
  File "/media/ntu/volume1/home/s124md303_06/.local/lib/python3.8/site-packages/tensorboard/backend/application.py", line 528, in __call__
    return self._app(environ, start_response)
  File "/media/ntu/volume1/home/s124md303_06/.local/lib/python3.8/site-packages/tensorboard/backend/application.py", line 569, in wrapper
    return wsgi_app(environ, start_response)
  File "/media/ntu/volume1/home/s124md303_06/.local/lib/python3.8/site-packages/tensorboard/backend/security_validator.py", line 91, in __call__
    return self._application(environ, start_response_proxy)
  File "/media/ntu/volume1/home/s124md303_06/.local/lib/python3.8/site-packages/tensorboard/backend/path_prefix.py", line 68, in __call__
    return self._application(environ, start_response)
  File "/media/ntu/volume1/home/s124md303_06/.local/lib/python3.8/site-packages/tensorboard/backend/experiment_id.py", line 73, in __call__
    return self._application(environ, start_response)
  File "/media/ntu/volume1/home/s124md303_06/.local/lib/python3.8/site-packages/tensorboard/backend/empty_path_redirect.py", line 43, in __call__
    return self._application(environ, start_response)
  File "/media/ntu/volume1/home/s124md303_06/.local/lib/python3.8/site-packages/tensorboard/backend/client_feature_flags.py", line 55, in __call__
    return self._application(environ, start_response)
  File "/media/ntu/volume1/home/s124md303_06/.local/lib/python3.8/site-packages/tensorboard/backend/auth_context_middleware.py", line 38, in __call__
    return self._application(environ, start_response)
  File "/media/ntu/volume1/home/s124md303_06/.local/lib/python3.8/site-packages/tensorboard/backend/application.py", line 551, in _route_request
    return self.exact_routes[clean_path](environ, start_response)
  File "/media/ntu/volume1/home/s124md303_06/.local/lib/python3.8/site-packages/werkzeug/wrappers/request.py", line 190, in application
    resp = f(*args[:-2] + (request,))
  File "/media/ntu/volume1/home/s124md303_06/.local/lib/python3.8/site-packages/tensorboard/plugins/hparams/hparams_plugin.py", line 122, in get_experiment_route
    json_format.MessageToJson(
TypeError: MessageToJson() got an unexpected keyword argument 'including_default_value_fields'
E0309 18:38:18.279841 140527362754304 _internal.py:97] Error on request:
Traceback (most recent call last):
  File "/media/ntu/volume1/home/s124md303_06/.local/lib/python3.8/site-packages/werkzeug/serving.py", line 370, in run_wsgi
    execute(self.server.app)
  File "/media/ntu/volume1/home/s124md303_06/.local/lib/python3.8/site-packages/werkzeug/serving.py", line 331, in execute
    application_iter = app(environ, start_response)
  File "/media/ntu/volume1/home/s124md303_06/.local/lib/python3.8/site-packages/tensorboard/backend/application.py", line 528, in __call__
    return self._app(environ, start_response)
  File "/media/ntu/volume1/home/s124md303_06/.local/lib/python3.8/site-packages/tensorboard/backend/application.py", line 569, in wrapper
    return wsgi_app(environ, start_response)
  File "/media/ntu/volume1/home/s124md303_06/.local/lib/python3.8/site-packages/tensorboard/backend/security_validator.py", line 91, in __call__
    return self._application(environ, start_response_proxy)
  File "/media/ntu/volume1/home/s124md303_06/.local/lib/python3.8/site-packages/tensorboard/backend/path_prefix.py", line 68, in __call__
    return self._application(environ, start_response)
  File "/media/ntu/volume1/home/s124md303_06/.local/lib/python3.8/site-packages/tensorboard/backend/experiment_id.py", line 73, in __call__
    return self._application(environ, start_response)
  File "/media/ntu/volume1/home/s124md303_06/.local/lib/python3.8/site-packages/tensorboard/backend/empty_path_redirect.py", line 43, in __call__
    return self._application(environ, start_response)
  File "/media/ntu/volume1/home/s124md303_06/.local/lib/python3.8/site-packages/tensorboard/backend/client_feature_flags.py", line 55, in __call__
    return self._application(environ, start_response)
  File "/media/ntu/volume1/home/s124md303_06/.local/lib/python3.8/site-packages/tensorboard/backend/auth_context_middleware.py", line 38, in __call__
    return self._application(environ, start_response)
  File "/media/ntu/volume1/home/s124md303_06/.local/lib/python3.8/site-packages/tensorboard/backend/application.py", line 551, in _route_request
    return self.exact_routes[clean_path](environ, start_response)
  File "/media/ntu/volume1/home/s124md303_06/.local/lib/python3.8/site-packages/werkzeug/wrappers/request.py", line 190, in application
    resp = f(*args[:-2] + (request,))
  File "/media/ntu/volume1/home/s124md303_06/.local/lib/python3.8/site-packages/tensorboard/plugins/hparams/hparams_plugin.py", line 122, in get_experiment_route
    json_format.MessageToJson(
TypeError: MessageToJson() got an unexpected keyword argument 'including_default_value_fields'
E0309 18:38:48.295395 140527362754304 _internal.py:97] Error on request:
Traceback (most recent call last):
  File "/media/ntu/volume1/home/s124md303_06/.local/lib/python3.8/site-packages/werkzeug/serving.py", line 370, in run_wsgi
    execute(self.server.app)
  File "/media/ntu/volume1/home/s124md303_06/.local/lib/python3.8/site-packages/werkzeug/serving.py", line 331, in execute
    application_iter = app(environ, start_response)
  File "/media/ntu/volume1/home/s124md303_06/.local/lib/python3.8/site-packages/tensorboard/backend/application.py", line 528, in __call__
    return self._app(environ, start_response)
  File "/media/ntu/volume1/home/s124md303_06/.local/lib/python3.8/site-packages/tensorboard/backend/application.py", line 569, in wrapper
    return wsgi_app(environ, start_response)
  File "/media/ntu/volume1/home/s124md303_06/.local/lib/python3.8/site-packages/tensorboard/backend/security_validator.py", line 91, in __call__
    return self._application(environ, start_response_proxy)
  File "/media/ntu/volume1/home/s124md303_06/.local/lib/python3.8/site-packages/tensorboard/backend/path_prefix.py", line 68, in __call__
    return self._application(environ, start_response)
  File "/media/ntu/volume1/home/s124md303_06/.local/lib/python3.8/site-packages/tensorboard/backend/experiment_id.py", line 73, in __call__
    return self._application(environ, start_response)
  File "/media/ntu/volume1/home/s124md303_06/.local/lib/python3.8/site-packages/tensorboard/backend/empty_path_redirect.py", line 43, in __call__
    return self._application(environ, start_response)
  File "/media/ntu/volume1/home/s124md303_06/.local/lib/python3.8/site-packages/tensorboard/backend/client_feature_flags.py", line 55, in __call__
    return self._application(environ, start_response)
  File "/media/ntu/volume1/home/s124md303_06/.local/lib/python3.8/site-packages/tensorboard/backend/auth_context_middleware.py", line 38, in __call__
    return self._application(environ, start_response)
  File "/media/ntu/volume1/home/s124md303_06/.local/lib/python3.8/site-packages/tensorboard/backend/application.py", line 551, in _route_request
    return self.exact_routes[clean_path](environ, start_response)
  File "/media/ntu/volume1/home/s124md303_06/.local/lib/python3.8/site-packages/werkzeug/wrappers/request.py", line 190, in application
    resp = f(*args[:-2] + (request,))
  File "/media/ntu/volume1/home/s124md303_06/.local/lib/python3.8/site-packages/tensorboard/plugins/hparams/hparams_plugin.py", line 122, in get_experiment_route
    json_format.MessageToJson(
TypeError: MessageToJson() got an unexpected keyword argument 'including_default_value_fields'
E0309 18:39:18.301724 140527488595712 _internal.py:97] Error on request:
Traceback (most recent call last):
  File "/media/ntu/volume1/home/s124md303_06/.local/lib/python3.8/site-packages/werkzeug/serving.py", line 370, in run_wsgi
    execute(self.server.app)
  File "/media/ntu/volume1/home/s124md303_06/.local/lib/python3.8/site-packages/werkzeug/serving.py", line 331, in execute
    application_iter = app(environ, start_response)
  File "/media/ntu/volume1/home/s124md303_06/.local/lib/python3.8/site-packages/tensorboard/backend/application.py", line 528, in __call__
    return self._app(environ, start_response)
  File "/media/ntu/volume1/home/s124md303_06/.local/lib/python3.8/site-packages/tensorboard/backend/application.py", line 569, in wrapper
    return wsgi_app(environ, start_response)
  File "/media/ntu/volume1/home/s124md303_06/.local/lib/python3.8/site-packages/tensorboard/backend/security_validator.py", line 91, in __call__
    return self._application(environ, start_response_proxy)
  File "/media/ntu/volume1/home/s124md303_06/.local/lib/python3.8/site-packages/tensorboard/backend/path_prefix.py", line 68, in __call__
    return self._application(environ, start_response)
  File "/media/ntu/volume1/home/s124md303_06/.local/lib/python3.8/site-packages/tensorboard/backend/experiment_id.py", line 73, in __call__
    return self._application(environ, start_response)
  File "/media/ntu/volume1/home/s124md303_06/.local/lib/python3.8/site-packages/tensorboard/backend/empty_path_redirect.py", line 43, in __call__
    return self._application(environ, start_response)
  File "/media/ntu/volume1/home/s124md303_06/.local/lib/python3.8/site-packages/tensorboard/backend/client_feature_flags.py", line 55, in __call__
    return self._application(environ, start_response)
  File "/media/ntu/volume1/home/s124md303_06/.local/lib/python3.8/site-packages/tensorboard/backend/auth_context_middleware.py", line 38, in __call__
    return self._application(environ, start_response)
  File "/media/ntu/volume1/home/s124md303_06/.local/lib/python3.8/site-packages/tensorboard/backend/application.py", line 551, in _route_request
    return self.exact_routes[clean_path](environ, start_response)
  File "/media/ntu/volume1/home/s124md303_06/.local/lib/python3.8/site-packages/werkzeug/wrappers/request.py", line 190, in application
    resp = f(*args[:-2] + (request,))
  File "/media/ntu/volume1/home/s124md303_06/.local/lib/python3.8/site-packages/tensorboard/plugins/hparams/hparams_plugin.py", line 122, in get_experiment_route
    json_format.MessageToJson(
TypeError: MessageToJson() got an unexpected keyword argument 'including_default_value_fields'
E0309 18:39:48.310884 140527530542848 _internal.py:97] Error on request:
Traceback (most recent call last):
  File "/media/ntu/volume1/home/s124md303_06/.local/lib/python3.8/site-packages/werkzeug/serving.py", line 370, in run_wsgi
    execute(self.server.app)
  File "/media/ntu/volume1/home/s124md303_06/.local/lib/python3.8/site-packages/werkzeug/serving.py", line 331, in execute
    application_iter = app(environ, start_response)
  File "/media/ntu/volume1/home/s124md303_06/.local/lib/python3.8/site-packages/tensorboard/backend/application.py", line 528, in __call__
    return self._app(environ, start_response)
  File "/media/ntu/volume1/home/s124md303_06/.local/lib/python3.8/site-packages/tensorboard/backend/application.py", line 569, in wrapper
    return wsgi_app(environ, start_response)
  File "/media/ntu/volume1/home/s124md303_06/.local/lib/python3.8/site-packages/tensorboard/backend/security_validator.py", line 91, in __call__
    return self._application(environ, start_response_proxy)
  File "/media/ntu/volume1/home/s124md303_06/.local/lib/python3.8/site-packages/tensorboard/backend/path_prefix.py", line 68, in __call__
    return self._application(environ, start_response)
  File "/media/ntu/volume1/home/s124md303_06/.local/lib/python3.8/site-packages/tensorboard/backend/experiment_id.py", line 73, in __call__
    return self._application(environ, start_response)
  File "/media/ntu/volume1/home/s124md303_06/.local/lib/python3.8/site-packages/tensorboard/backend/empty_path_redirect.py", line 43, in __call__
    return self._application(environ, start_response)
  File "/media/ntu/volume1/home/s124md303_06/.local/lib/python3.8/site-packages/tensorboard/backend/client_feature_flags.py", line 55, in __call__
    return self._application(environ, start_response)
  File "/media/ntu/volume1/home/s124md303_06/.local/lib/python3.8/site-packages/tensorboard/backend/auth_context_middleware.py", line 38, in __call__
    return self._application(environ, start_response)
  File "/media/ntu/volume1/home/s124md303_06/.local/lib/python3.8/site-packages/tensorboard/backend/application.py", line 551, in _route_request
    return self.exact_routes[clean_path](environ, start_response)
  File "/media/ntu/volume1/home/s124md303_06/.local/lib/python3.8/site-packages/werkzeug/wrappers/request.py", line 190, in application
    resp = f(*args[:-2] + (request,))
  File "/media/ntu/volume1/home/s124md303_06/.local/lib/python3.8/site-packages/tensorboard/plugins/hparams/hparams_plugin.py", line 122, in get_experiment_route
    json_format.MessageToJson(
TypeError: MessageToJson() got an unexpected keyword argument 'including_default_value_fields'
E0309 18:40:18.326644 140527362754304 _internal.py:97] Error on request:
Traceback (most recent call last):
  File "/media/ntu/volume1/home/s124md303_06/.local/lib/python3.8/site-packages/werkzeug/serving.py", line 370, in run_wsgi
    execute(self.server.app)
  File "/media/ntu/volume1/home/s124md303_06/.local/lib/python3.8/site-packages/werkzeug/serving.py", line 331, in execute
    application_iter = app(environ, start_response)
  File "/media/ntu/volume1/home/s124md303_06/.local/lib/python3.8/site-packages/tensorboard/backend/application.py", line 528, in __call__
    return self._app(environ, start_response)
  File "/media/ntu/volume1/home/s124md303_06/.local/lib/python3.8/site-packages/tensorboard/backend/application.py", line 569, in wrapper
    return wsgi_app(environ, start_response)
  File "/media/ntu/volume1/home/s124md303_06/.local/lib/python3.8/site-packages/tensorboard/backend/security_validator.py", line 91, in __call__
    return self._application(environ, start_response_proxy)
  File "/media/ntu/volume1/home/s124md303_06/.local/lib/python3.8/site-packages/tensorboard/backend/path_prefix.py", line 68, in __call__
    return self._application(environ, start_response)
  File "/media/ntu/volume1/home/s124md303_06/.local/lib/python3.8/site-packages/tensorboard/backend/experiment_id.py", line 73, in __call__
    return self._application(environ, start_response)
  File "/media/ntu/volume1/home/s124md303_06/.local/lib/python3.8/site-packages/tensorboard/backend/empty_path_redirect.py", line 43, in __call__
    return self._application(environ, start_response)
  File "/media/ntu/volume1/home/s124md303_06/.local/lib/python3.8/site-packages/tensorboard/backend/client_feature_flags.py", line 55, in __call__
    return self._application(environ, start_response)
  File "/media/ntu/volume1/home/s124md303_06/.local/lib/python3.8/site-packages/tensorboard/backend/auth_context_middleware.py", line 38, in __call__
    return self._application(environ, start_response)
  File "/media/ntu/volume1/home/s124md303_06/.local/lib/python3.8/site-packages/tensorboard/backend/application.py", line 551, in _route_request
    return self.exact_routes[clean_path](environ, start_response)
  File "/media/ntu/volume1/home/s124md303_06/.local/lib/python3.8/site-packages/werkzeug/wrappers/request.py", line 190, in application
    resp = f(*args[:-2] + (request,))
  File "/media/ntu/volume1/home/s124md303_06/.local/lib/python3.8/site-packages/tensorboard/plugins/hparams/hparams_plugin.py", line 122, in get_experiment_route
    json_format.MessageToJson(
TypeError: MessageToJson() got an unexpected keyword argument 'including_default_value_fields'
E0309 18:40:48.346832 140527446648576 _internal.py:97] Error on request:
Traceback (most recent call last):
  File "/media/ntu/volume1/home/s124md303_06/.local/lib/python3.8/site-packages/werkzeug/serving.py", line 370, in run_wsgi
    execute(self.server.app)
  File "/media/ntu/volume1/home/s124md303_06/.local/lib/python3.8/site-packages/werkzeug/serving.py", line 331, in execute
    application_iter = app(environ, start_response)
  File "/media/ntu/volume1/home/s124md303_06/.local/lib/python3.8/site-packages/tensorboard/backend/application.py", line 528, in __call__
    return self._app(environ, start_response)
  File "/media/ntu/volume1/home/s124md303_06/.local/lib/python3.8/site-packages/tensorboard/backend/application.py", line 569, in wrapper
    return wsgi_app(environ, start_response)
  File "/media/ntu/volume1/home/s124md303_06/.local/lib/python3.8/site-packages/tensorboard/backend/security_validator.py", line 91, in __call__
    return self._application(environ, start_response_proxy)
  File "/media/ntu/volume1/home/s124md303_06/.local/lib/python3.8/site-packages/tensorboard/backend/path_prefix.py", line 68, in __call__
    return self._application(environ, start_response)
  File "/media/ntu/volume1/home/s124md303_06/.local/lib/python3.8/site-packages/tensorboard/backend/experiment_id.py", line 73, in __call__
    return self._application(environ, start_response)
  File "/media/ntu/volume1/home/s124md303_06/.local/lib/python3.8/site-packages/tensorboard/backend/empty_path_redirect.py", line 43, in __call__
    return self._application(environ, start_response)
  File "/media/ntu/volume1/home/s124md303_06/.local/lib/python3.8/site-packages/tensorboard/backend/client_feature_flags.py", line 55, in __call__
    return self._application(environ, start_response)
  File "/media/ntu/volume1/home/s124md303_06/.local/lib/python3.8/site-packages/tensorboard/backend/auth_context_middleware.py", line 38, in __call__
    return self._application(environ, start_response)
  File "/media/ntu/volume1/home/s124md303_06/.local/lib/python3.8/site-packages/tensorboard/backend/application.py", line 551, in _route_request
    return self.exact_routes[clean_path](environ, start_response)
  File "/media/ntu/volume1/home/s124md303_06/.local/lib/python3.8/site-packages/werkzeug/wrappers/request.py", line 190, in application
    resp = f(*args[:-2] + (request,))
  File "/media/ntu/volume1/home/s124md303_06/.local/lib/python3.8/site-packages/tensorboard/plugins/hparams/hparams_plugin.py", line 122, in get_experiment_route
    json_format.MessageToJson(
TypeError: MessageToJson() got an unexpected keyword argument 'including_default_value_fields'
TensorBoard caught SIGTERM; exiting...
